Workbook

Sheet 库存看板
A1: 针织服装企业库存看板 | B1: 针织服装企业库存看板 | C1: 针织服装企业库存看板 | D1: 针织服装企业库存看板 | E1: 针织服装企业库存看板 | F1: 针织服装企业库存看板 | G1: 针织服装企业库存看板 | H1: 针织服装企业库存看板 | I1: 针织服装企业库存看板 | J1: 针织服装企业库存看板 | K1: 针织服装企业库存看板 | L1: 针织服装企业库存看板 | M1: 针织服装企业库存看板 | N1: 针织服装企业库存看板
A3: 自动汇总纱线、面料、辅料库存与预警；适用于横机、裁剪、缝制、后道领料 | B3: 自动汇总纱线、面料、辅料库存与预警；适用于横机、裁剪、缝制、后道领料 | C3: 自动汇总纱线、面料、辅料库存与预警；适用于横机、裁剪、缝制、后道领料 | D3: 自动汇总纱线、面料、辅料库存与预警；适用于横机、裁剪、缝制、后道领料 | E3: 自动汇总纱线、面料、辅料库存与预警；适用于横机、裁剪、缝制、后道领料 | F3: 自动汇总纱线、面料、辅料库存与预警；适用于横机、裁剪、缝制、后道领料 | G3: 自动汇总纱线、面料、辅料库存与预警；适用于横机、裁剪、缝制、后道领料 | H3: 自动汇总纱线、面料、辅料库存与预警；适用于横机、裁剪、缝制、后道领料 | I3: 自动汇总纱线、面料、辅料库存与预警；适用于横机、裁剪、缝制、后道领料 | J3: 自动汇总纱线、面料、辅料库存与预警；适用于横机、裁剪、缝制、后道领料 | K3: 自动汇总纱线、面料、辅料库存与预警；适用于横机、裁剪、缝制、后道领料 | L3: 自动汇总纱线、面料、辅料库存与预警；适用于横机、裁剪、缝制、后道领料 | M3: 自动汇总纱线、面料、辅料库存与预警；适用于横机、裁剪、缝制、后道领料 | N3: 自动汇总纱线、面料、辅料库存与预警；适用于横机、裁剪、缝制、后道领料
A5: 物料总数 | B5: 预警物料 | C5: 订单缺料 | D5: 负库存
A6: =COUNTA(库存总账!$A$5:$A$164) -> 160 | B6: =COUNTIF(库存总账!$K$5:$K$164,"<>正常") -> 154 | C6: =COUNTIF(库存总账!$K$5:$K$164,"订单缺料") -> 5 | D6: =COUNTIF(库存总账!$K$5:$K$164,"负库存") -> 0
A8: 按物料类型汇总 | B8: 按物料类型汇总 | C8: 按物料类型汇总 | D8: 按物料类型汇总 | E8: 按物料类型汇总 | F8: 按物料类型汇总 | H8: 预警清单 Top 20 | I8: 预警清单 Top 20 | J8: 预警清单 Top 20 | K8: 预警清单 Top 20 | L8: 预警清单 Top 20 | M8: 预警清单 Top 20 | N8: 预警清单 Top 20
A9: 物料类型 | B9: 订单需求 | C9: 合格入库 | D9: 已出库 | E9: 账面库存 | F9: 预警数 | H9: 物料编码 | I9: 物料名称 | J9: 类型 | K9: 库存 | L9: 订单需求 | M9: 预警状态 | N9: 建议补货
A10: 纱线 | B10: =SUMIFS(库存总账!$F$5:$F$164,库存总账!$C$5:$C$164,A10) -> 9747.9406 | C10: =SUMIFS(库存总账!$G$5:$G$164,库存总账!$C$5:$C$164,A10) -> 2009.65 | D10: =SUMIFS(库存总账!$H$5:$H$164,库存总账!$C$5:$C$164,A10) -> 614.185 | E10: =SUMIFS(库存总账!$I$5:$I$164,库存总账!$C$5:$C$164,A10) -> 1395.465 | F10: =COUNTIFS(库存总账!$C$5:$C$164,A10,库存总账!$K$5:$K$164,"<>正常") -> 56 | H10: =IF(库存总账!$K5="正常","",库存总账!$A5) -> MAT-0001 | I10: =IF(库存总账!$K5="正常","",库存总账!$B5) -> 市场面料格子 | J10: =IF(库存总账!$K5="正常","",库存总账!$C5) -> 面料 | K10: =IF(库存总账!$K5="正常","",库存总账!$I5) -> 0 | L10: =IF(库存总账!$K5="正常","",库存总账!$F5) -> 0 | M10: =IF(库存总账!$K5="正常","",库存总账!$K5) -> 低于安全库存 | N10: =IF(库存总账!$K5="正常","",库存总账!$L5) -> 80
A11: 面料 | B11: =SUMIFS(库存总账!$F$5:$F$164,库存总账!$C$5:$C$164,A11) -> 42172.762 | C11: =SUMIFS(库存总账!$G$5:$G$164,库存总账!$C$5:$C$164,A11) -> 12769.1 | D11: =SUMIFS(库存总账!$H$5:$H$164,库存总账!$C$5:$C$164,A11) -> 1833.547 | E11: =SUMIFS(库存总账!$I$5:$I$164,库存总账!$C$5:$C$164,A11) -> 10935.553 | F11: =COUNTIFS(库存总账!$C$5:$C$164,A11,库存总账!$K$5:$K$164,"<>正常") -> 95 | H11: =IF(库存总账!$K6="正常","",库存总账!$A6) -> MAT-0002 | I11: =IF(库存总账!$K6="正常","",库存总账!$B6) -> 150D全涤线 | J11: =IF(库存总账!$K6="正常","",库存总账!$C6) -> 纱线 | K11: =IF(库存总账!$K6="正常","",库存总账!$I6) -> 579.15 | L11: =IF(库存总账!$K6="正常","",库存总账!$F6) -> 917.73 | M11: =IF(库存总账!$K6="正常","",库存总账!$K6) -> 订单缺料 | N11: =IF(库存总账!$K6="正常","",库存总账!$L6) -> 368.58
A12: 辅料 | B12: =SUMIFS(库存总账!$F$5:$F$164,库存总账!$C$5:$C$164,A12) -> 2709.315 | C12: =SUMIFS(库存总账!$G$5:$G$164,库存总账!$C$5:$C$164,A12) -> 7.8 | D12: =SUMIFS(库存总账!$H$5:$H$164,库存总账!$C$5:$C$164,A12) -> 3.51 | E12: =SUMIFS(库存总账!$I$5:$I$164,库存总账!$C$5:$C$164,A12) -> 4.29 | F12: =COUNTIFS(库存总账!$C$5:$C$164,A12,库存总账!$K$5:$K$164,"<>正常") -> 3 | H12: =IF(库存总账!$K7="正常","",库存总账!$A7) -> MAT-0003 | I12: =IF(库存总账!$K7="正常","",库存总账!$B7) -> 面料F01752 | J12: =IF(库存总账!$K7="正常","",库存总账!$C7) -> 面料 | K12: =IF(库存总账!$K7="正常","",库存总账!$I7) -> 1404 | L12: =IF(库存总账!$K7="正常","",库存总账!$F7) -> 2268 | M12: =IF(库存总账!$K7="正常","",库存总账!$K7) -> 订单缺料 | N12: =IF(库存总账!$K7="正常","",库存总账!$L7) -> 944
H13: =IF(库存总账!$K8="正常","",库存总账!$A8) -> MAT-0004 | I13: =IF(库存总账!$K8="正常","",库存总账!$B8) -> 面料F05140 | J13: =IF(库存总账!$K8="正常","",库存总账!$C8) -> 面料 | K13: =IF(库存总账!$K8="正常","",库存总账!$I8) -> 31.2 | L13: =IF(库存总账!$K8="正常","",库存总账!$F8) -> 50.4 | M13: =IF(库存总账!$K8="正常","",库存总账!$K8) -> 低于安全库存 | N13: =IF(库存总账!$K8="正常","",库存总账!$L8) -> 99.2
H14: =IF(库存总账!$K9="正常","",库存总账!$A9) | I14: =IF(库存总账!$K9="正常","",库存总账!$B9) | J14: =IF(库存总账!$K9="正常","",库存总账!$C9) | K14: =IF(库存总账!$K9="正常","",库存总账!$I9) | L14: =IF(库存总账!$K9="正常","",库存总账!$F9) | M14: =IF(库存总账!$K9="正常","",库存总账!$K9) | N14: =IF(库存总账!$K9="正常","",库存总账!$L9)
H15: =IF(库存总账!$K10="正常","",库存总账!$A10) | I15: =IF(库存总账!$K10="正常","",库存总账!$B10) | J15: =IF(库存总账!$K10="正常","",库存总账!$C10) | K15: =IF(库存总账!$K10="正常","",库存总账!$I10) | L15: =IF(库存总账!$K10="正常","",库存总账!$F10) | M15: =IF(库存总账!$K10="正常","",库存总账!$K10) | N15: =IF(库存总账!$K10="正常","",库存总账!$L10)
H16: =IF(库存总账!$K11="正常","",库存总账!$A11) | I16: =IF(库存总账!$K11="正常","",库存总账!$B11) | J16: =IF(库存总账!$K11="正常","",库存总账!$C11) | K16: =IF(库存总账!$K11="正常","",库存总账!$I11) | L16: =IF(库存总账!$K11="正常","",库存总账!$F11) | M16: =IF(库存总账!$K11="正常","",库存总账!$K11) | N16: =IF(库存总账!$K11="正常","",库存总账!$L11)
H17: =IF(库存总账!$K12="正常","",库存总账!$A12) | I17: =IF(库存总账!$K12="正常","",库存总账!$B12) | J17: =IF(库存总账!$K12="正常","",库存总账!$C12) | K17: =IF(库存总账!$K12="正常","",库存总账!$I12) | L17: =IF(库存总账!$K12="正常","",库存总账!$F12) | M17: =IF(库存总账!$K12="正常","",库存总账!$K12) | N17: =IF(库存总账!$K12="正常","",库存总账!$L12)
H18: =IF(库存总账!$K13="正常","",库存总账!$A13) | I18: =IF(库存总账!$K13="正常","",库存总账!$B13) | J18: =IF(库存总账!$K13="正常","",库存总账!$C13) | K18: =IF(库存总账!$K13="正常","",库存总账!$I13) | L18: =IF(库存总账!$K13="正常","",库存总账!$F13) | M18: =IF(库存总账!$K13="正常","",库存总账!$K13) | N18: =IF(库存总账!$K13="正常","",库存总账!$L13)
H19: =IF(库存总账!$K14="正常","",库存总账!$A14) -> MAT-0010 | I19: =IF(库存总账!$K14="正常","",库存总账!$B14) -> 客供毛圈 | J19: =IF(库存总账!$K14="正常","",库存总账!$C14) -> 纱线 | K19: =IF(库存总账!$K14="正常","",库存总账!$I14) -> 28.05 | L19: =IF(库存总账!$K14="正常","",库存总账!$F14) -> 52.53 | M19: =IF(库存总账!$K14="正常","",库存总账!$K14) -> 低于安全库存 | N19: =IF(库存总账!$K14="正常","",库存总账!$L14) -> 54.48
H20: =IF(库存总账!$K15="正常","",库存总账!$A15) -> MAT-0011 | I20: =IF(库存总账!$K15="正常","",库存总账!$B15) -> 2*2罗文 | J20: =IF(库存总账!$K15="正常","",库存总账!$C15) -> 辅料 | K20: =IF(库存总账!$K15="正常","",库存总账!$I15) -> 4.29 | L20: =IF(库存总账!$K15="正常","",库存总账!$F15) -> 8.19 | M20: =IF(库存总账!$K15="正常","",库存总账!$K15) -> 低于安全库存 | N20: =IF(库存总账!$K15="正常","",库存总账!$L15) -> 103.9
H21: =IF(库存总账!$K16="正常","",库存总账!$A16) -> MAT-0012 | I21: =IF(库存总账!$K16="正常","",库存总账!$B16) -> 20/1汗布 | J21: =IF(库存总账!$K16="正常","",库存总账!$C16) -> 面料 | K21: =IF(库存总账!$K16="正常","",库存总账!$I16) -> 2.475 | L21: =IF(库存总账!$K16="正常","",库存总账!$F16) -> 4.725 | M21: =IF(库存总账!$K16="正常","",库存总账!$K16) -> 低于安全库存 | N21: =IF(库存总账!$K16="正常","",库存总账!$L16) -> 82.25
H22: =IF(库存总账!$K17="正常","",库存总账!$A17) -> MAT-0013 | I22: =IF(库存总账!$K17="正常","",库存总账!$B17) -> F00921 | J22: =IF(库存总账!$K17="正常","",库存总账!$C17) -> 面料 | K22: =IF(库存总账!$K17="正常","",库存总账!$I17) -> 114.94 | L22: =IF(库存总账!$K17="正常","",库存总账!$F17) -> 217.14 | M22: =IF(库存总账!$K17="正常","",库存总账!$K17) -> 订单缺料 | N22: =IF(库存总账!$K17="正常","",库存总账!$L17) -> 182.2
H23: =IF(库存总账!$K18="正常","",库存总账!$A18) -> MAT-0014 | I23: =IF(库存总账!$K18="正常","",库存总账!$B18) -> 索罗娜罗纹 | J23: =IF(库存总账!$K18="正常","",库存总账!$C18) -> 面料 | K23: =IF(库存总账!$K18="正常","",库存总账!$I18) -> 22.772 | L23: =IF(库存总账!$K18="正常","",库存总账!$F18) -> 35.532 | M23: =IF(库存总账!$K18="正常","",库存总账!$K18) -> 低于安全库存 | N23: =IF(库存总账!$K18="正常","",库存总账!$L18) -> 92.76
H24: =IF(库存总账!$K19="正常","",库存总账!$A19) -> MAT-0015 | I24: =IF(库存总账!$K19="正常","",库存总账!$B19) -> 客供毛圈 | J24: =IF(库存总账!$K19="正常","",库存总账!$C19) -> 纱线 | K24: =IF(库存总账!$K19="正常","",库存总账!$I19) -> 31.68 | L24: =IF(库存总账!$K19="正常","",库存总账!$F19) -> 59.328 | M24: =IF(库存总账!$K19="正常","",库存总账!$K19) -> 订单缺料 | N24: =IF(库存总账!$K19="正常","",库存总账!$L19) -> 57.648
... H29: =IF(库存总账!$K24="正常","",库存总账!$A24) -> MAT-0020 | I29: =IF(库存总账!$K24="正常","",库存总账!$B24) -> 氨纶丝 | J29: =IF(库存总账!$K24="正常","",库存总账!$C24) -> 纱线 | K29: =IF(库存总账!$K24="正常","",库存总账!$I24) -> 16.53 | L29: =IF(库存总账!$K24="正常","",库存总账!$F24) -> 6.18 | M29: =IF(库存总账!$K24="正常","",库存总账!$K24) -> 低于安全库存 | N29: =IF(库存总账!$K24="正常","",库存总账!$L24) -> 19.65

Sheet 订单主数据
A1: 订单主数据 - 从生产管理进度表承接 | B1: 订单主数据 - 从生产管理进度表承接 | C1: 订单主数据 - 从生产管理进度表承接 | D1: 订单主数据 - 从生产管理进度表承接 | E1: 订单主数据 - 从生产管理进度表承接 | F1: 订单主数据 - 从生产管理进度表承接 | G1: 订单主数据 - 从生产管理进度表承接 | H1: 订单主数据 - 从生产管理进度表承接 | I1: 订单主数据 - 从生产管理进度表承接 | J1: 订单主数据 - 从生产管理进度表承接 | K1: 订单主数据 - 从生产管理进度表承接 | L1: 订单主数据 - 从生产管理进度表承接 | M1: 订单主数据 - 从生产管理进度表承接 | N1: 订单主数据 - 从生产管理进度表承接 | O1: 订单主数据 - 从生产管理进度表承接 | P1: 订单主数据 - 从生产管理进度表承接 | Q1: 订单主数据 - 从生产管理进度表承接 | R1: 订单主数据 - 从生产管理进度表承接 | S1: 订单主数据 - 从生产管理进度表承接 | T1: 订单主数据 - 从生产管理进度表承接
A3: 保留生产进度表的订单、款号、素材、供应商、数量、船期和工厂字段，供 BOM/入库/出库引用 | B3: 保留生产进度表的订单、款号、素材、供应商、数量、船期和工厂字段，供 BOM/入库/出库引用 | C3: 保留生产进度表的订单、款号、素材、供应商、数量、船期和工厂字段，供 BOM/入库/出库引用 | D3: 保留生产进度表的订单、款号、素材、供应商、数量、船期和工厂字段，供 BOM/入库/出库引用 | E3: 保留生产进度表的订单、款号、素材、供应商、数量、船期和工厂字段，供 BOM/入库/出库引用 | F3: 保留生产进度表的订单、款号、素材、供应商、数量、船期和工厂字段，供 BOM/入库/出库引用 | G3: 保留生产进度表的订单、款号、素材、供应商、数量、船期和工厂字段，供 BOM/入库/出库引用 | H3: 保留生产进度表的订单、款号、素材、供应商、数量、船期和工厂字段，供 BOM/入库/出库引用 | I3: 保留生产进度表的订单、款号、素材、供应商、数量、船期和工厂字段，供 BOM/入库/出库引用 | J3: 保留生产进度表的订单、款号、素材、供应商、数量、船期和工厂字段，供 BOM/入库/出库引用 | K3: 保留生产进度表的订单、款号、素材、供应商、数量、船期和工厂字段，供 BOM/入库/出库引用 | L3: 保留生产进度表的订单、款号、素材、供应商、数量、船期和工厂字段，供 BOM/入库/出库引用 | M3: 保留生产进度表的订单、款号、素材、供应商、数量、船期和工厂字段，供 BOM/入库/出库引用 | N3: 保留生产进度表的订单、款号、素材、供应商、数量、船期和工厂字段，供 BOM/入库/出库引用 | O3: 保留生产进度表的订单、款号、素材、供应商、数量、船期和工厂字段，供 BOM/入库/出库引用 | P3: 保留生产进度表的订单、款号、素材、供应商、数量、船期和工厂字段，供 BOM/入库/出库引用 | Q3: 保留生产进度表的订单、款号、素材、供应商、数量、船期和工厂字段，供 BOM/入库/出库引用 | R3: 保留生产进度表的订单、款号、素材、供应商、数量、船期和工厂字段，供 BOM/入库/出库引用 | S3: 保留生产进度表的订单、款号、素材、供应商、数量、船期和工厂字段，供 BOM/入库/出库引用 | T3: 保留生产进度表的订单、款号、素材、供应商、数量、船期和工厂字段，供 BOM/入库/出库引用
A4: 来源表 | B4: 业务员 | C4: 登记日期 | D4: 客户 | E4: 品牌 | F4: 合同/销售单号 | G4: 品番 | H4: 样品款号 | I4: 款式 | J4: 素材 | K4: 供应商 | L4: 订单数量 | M4: 船期 | N4: 材料采购状态 | O4: 原料到库日期 | P4: 辅料到库日期 | Q4: 横机/毛衫工厂 | R4: 缝制/服装工厂 | S4: 后道工厂 | T4: 备注
A5: 2026年度生产进度 | B5: 季晓芳 | C5: 2024-01-01 | D5: 秦 | F5: 历史订单 | G5: 暂无 | H5: 361446 | I5: 女士V领针织 | J5: 市场面料格子 | L5: 695 | M5: 2022-05-30
A6: 2026年度生产进度 | B6: 王曼曼 | C6: 2025-07-19 | D6: 片山 | E6: MN | F6: SO250714-252 | G6: 66SPSM611 | H6: 66SPSM509 | I6: 男士毛衣开衫 | J6: 150D全涤线 | L6: 2700 | M6: 2026-01-23
A7: 2026年度生产进度 | B7: 杨义 | C7: 2025-10-20 | D7: 玉田 | E7: T2 | F7: SO251020-722 | G7: 42-14-0299-639 | H7: 25FW1427 | I7: 男士针织T恤衫 | J7: 面料F01752+面料F05140 | K7: 鸿澄 | L7: 2400 | M7: 2026-01-02
A8: 2026年度生产进度 | B8: 张彐南 | C8: 2025-08-20 | D8: 尾方 | F8: SO260318-1579 | G8: 12-04-0209-802 | H8: 26S-BM0406 | I8: 男士T恤 | J8: F04595 全涤华夫格+F04858全涤螺纹 | L8: 850 | M8: 2026-01-23
A9: 2026年度生产进度 | B9: 张彐南 | C9: 2025-08-21 | D9: 尾方 | F9: SO260318-1581 | G9: 11-05-0145-803 | H9: 26S-BM0501 | I9: 男士条纹毛衣 | J9: 150D涤丝 | L9: 1108 | M9: 2026-01-23
A10: 2026年度生产进度 | B10: 张彐南 | C10: 2025-08-21 | D10: 尾方 | F10: SO260318-1590 | G10: 11-13-2266-803 | H10: 26S-BM1313 | I10: 男士针织拉链开衫 | J10: F05721 精编空花 | L10: 1628 | M10: 2026-01-23
A11: 2026年度生产进度 | B11: 张彐南 | C11: 2025-11-27 | D11: 尾方 | F11: SO260318-1577 | G11: 11-13-1661-803 | H11: 26S-HE1301 | I11: 男士风帽套头衫 | J11: 客供毛圈+2*2罗文+20/1汗布 | L11: 30 | M11: 2026-01-23
A12: 2026年度生产进度 | B12: 杨义 | C12: 2025-10-22 | D12: 玉田 | E12: T2 | F12: SO260319-1607 | G12: 6-0086-1-53-201 | H12: 6-0086-1-53-901 | I12: 圆领套头衫 | J12: F00921+索罗娜罗纹 | L12: 188 | M12: 2026-01-09
A13: 2026年度生产进度 | B13: 张彐南 | C13: 2025-11-27 | D13: 尾方 | F13: SO260318-1578 | G13: 11-24-3533-803 | H13: 26S-HE2402 | I13: 男士长裤 | J13: 客供毛圈+网眼袋布 | L13: 30 | M13: 2026-01-23
A14: 2026年度生产进度 | B14: 杨义 | C14: 2025-11-19 | D14: 玉田 | E14: T2 | F14: SO251119-995 | G14: 26-080-312-5000-1-0 | H14: 26417-3 | I14: 男士毛衣POLO衫 | J14: 150D中弹丝+雪尼尔+氨纶丝 | K14: 奕翔/伟强/恒升 | L14: 300 | M14: 2026-01-09
A15: 2026年度生产进度 | B15: 杨义 | C15: 2025-11-21 | D15: 玉田 | E15: T2 | F15: SO251205-1093 | G15: 616-35027 | H15: 26TK08 | I15: 男士针织毛毯针套头衫 | J15: 240克空气层 | L15: 750 | M15: 2026-01-16
A16: 2026年度生产进度 | B16: 王曼曼 | C16: 2025-10-20 | D16: 片山 | E16: MN | F16: SO251018-708 | G16: 1612-1-000024 | H16: BY-F02666 | I16: 女士针织T | J16: 面料F02666+面料F03181 | L16: 1500 | M16: 2026-01-30
A17: 2026年度生产进度 | B17: 杨义 | C17: 2025-12-05 | D17: 玉田 | E17: T2 | F17: SO251205-1091 | G17: 616-35026 | H17: 616-35026 | I17: 男士针织套头衫 | J17: 240克棉涤氨纶空气层 | L17: 2000 | M17: 2026-01-16
A18: 2026年度生产进度 | B18: 丁佐华 | C18: 2025-08-06 | D18: 今村 | F18: SO250806-336 | G18: KKWMLM0333 | H18: 26SS-MN-021(26SS-MN-008) | I18: 女士针织T恤 | J18: 面料F06037 | L18: 1037 | M18: 2026-01-29
A19: 2026年度生产进度 | B19: 丁佐华 | C19: 2025-08-06 | D19: 今村 | F19: SO250806-338 | G19: KKWMLM0331 | H19: 26SS-MN-004 | I19: 女士针织套头衫 | J19: 面料F05915+日本别布 | L19: 628 | M19: 2026-02-07
A20: 2026年度生产进度 | B20: 蒋建芳 | C20: 2025-08-13 | D20: 国武 | F20: SO250809-343 | G20: 102439090005 | H20: 25SS-CL102（251-1243） | I20: 男士毛衣拼接中国结上衣 | J20: 2/36麻纱线 | L20: 50 | M20: 2026-01-13
A21: 2026年度生产进度 | B21: 蒋建芳 | C21: 2025-08-13 | D21: 国武 | F21: SO250811-349 | G21: 102439090006 | H21: 25SS-CL103（251-1244） | I21: 男士毛衣拼接上衣 | J21: 2/36麻纱线 | L21: 50 | M21: 2026-01-13
A22: 2026年度生产进度 | B22: 蒋建芳 | C22: 2025-08-13 | D22: 国武 | F22: SO250811-350 | G22: 1043390900068 | H22: 25SS-CL104（251-1452） | I22: 男士毛衣拼接长裤 | J22: 2/36麻纱线+三维尔麻梭织布 | L22: 50 | M22: 2026-01-13
A23: 2026年度生产进度 | B23: 蒋建芳 | C23: 2025-08-13 | D23: 国武 | F23: SO260318-1602 | G23: 102439090004 | H23: 25SS-CL100（251-1242） | I23: 男士毛衣拼接风帽衫 | J23: 2/36麻纱线+三维尔麻梭织布 | L23: 50 | M23: 2026-01-13
A24: 2026年度生产进度 | B24: 蒋建芳 | C24: 2025-08-13 | D24: 国武 | F24: SO250811-347 | G24: 1080390900003 | H24: 25SS-CL101（251-1805） | I24: 毛衣拼接围巾 | J24: 2/36麻纱线 | L24: 50 | M24: 2026-01-30
A25: 2026年度生产进度 | B25: 张彐南 | C25: 2025-12-06 | D25: 船木 | F25: SO251206-1103 | G25: 51P13-713 | H25: 1P-TK14 | I25: 男士针织拼接T恤 | J25: 150D全涤线+丝光广东棉毛布 | K25: 恒升 | L25: 1400 | M25: 2026-01-27
A26: 2026年度生产进度 | B26: 丁佐华 | C26: 2025-08-19 | D26: 渡边 | F26: SO250819-379 | G26: 3612-1-000026 | H26: GLS261CS-04 | I26: 女士成衣染色套头衫 | J26: 面料F04411+2*2罗文面料 | L26: 2000 | M26: 2026-01-12
A27: 2026年度生产进度 | B27: 丁佐华 | C27: 2025-08-19 | D27: 渡边 | F27: SO250819-383 | G27: 3612-1-000027 | H27: GLS261CS-08 | I27: 成衣染色POLO衫 | J27: 面料F04411+2*2棉氨纶螺纹+全棉纱线+面料F00130A | L27: 800 | M27: 2026-01-12
A28: 2026年度生产进度 | B28: 张彐南 | C28: 2025-10-21 | D28: 船木 | F28: SO251021-732 | G28: J1P83-020 | H28: J1P83-020 | I28: 男士针织长袖T恤 | J28: 罗文+棉毛布 | L28: 550 | M28: 2026-01-30
A29: 2026年度生产进度 | B29: 张彐南 | C29: 2025-10-21 | D29: 船木 | F29: SO251021-733 | G29: J1P85-020 | H29: J1P85-020 | I29: 男士针织V领T恤 | J29: 罗文+棉毛布 | L29: 600 | M29: 2026-01-30
A30: 2026年度生产进度 | B30: 张彐南 | C30: 2025-10-21 | D30: 船木 | F30: SO251021-731 | G30: J1P80-020 | H30: J1P80-020 | I30: 男士针织短袖T恤 | J30: 罗文+棉毛布 | L30: 3088 | M30: 2026-02-06
A31: 2026年度生产进度 | B31: 张彐南 | C31: 2025-08-18 | D31: 尾方 | F31: SO260318-1596 | G31: 11-04-1321-803 | H31: 26S-BM0414 | I31: 男士T恤 | J31: F05172+F04754 | L31: 3860 | M31: 2026-02-13
A32: 2026年度生产进度 | B32: 陈韦韦 | C32: 2025-08-22 | D32: 江本 | F32: SO250822-408 | G32: HM31CS002 | H32: HM31CS002 | I32: 男款短袖T恤 | J32: 面料F05457+1*1罗纹 | L32: 2731 | M32: 2026-01-02
A33: 2026年度生产进度 | B33: 陈韦韦 | C33: 2025-08-22 | D33: 江本 | F33: SO250822-407-1 | G33: HM31CS020 | H33: HM31CS020 | I33: 男款半开襟长袖套头衫 | J33: 客供网眼面料+客供圆筒罗纹面料 | L33: 477 | M33: 2026-01-13
A34: 2026年度生产进度 | B34: 陈韦韦 | C34: 2025-08-22 | D34: 江本 | F34: SO250822-409 | G34: HM31CS003 | H34: HM31CS003 | I34: 男款针织开衫 | J34: 客供起毛毛圈+客供梭织布+罗纹布 | L34: 111 | M34: 2026-01-13
A35: 2026年度生产进度 | B35: 陈韦韦 | C35: 2025-08-22 | D35: 江本 | F35: SO250822-407-2 | G35: HM31CS020 | H35: HM31CS020 | I35: 男款半开襟长袖套头衫 | J35: 客供网眼面料+客供圆筒罗纹面料 | L35: 457 | M35: 2026-01-26
A36: 2026年度生产进度 | B36: 季晓芳 | C36: 2025-08-30 | D36: 本村 | E36: LANDWELL | F36: SO250827-427 | G36: CH02-1268 | H36: CH02-1268 | I36: 男士绣花PO衫 | J36: 面料F03861+21双纱+高弹丝+面料F00368+面料F00369 | L36: 1213 | M36: 2026-01-10
A37: 2026年度生产进度 | B37: 季晓芳 | C37: 2025-08-30 | D37: 本村 | E37: LANDWELL | F37: SO250827-428 | G37: CH12-1268 | H37: CH12-1268 | I37: 女士绣花PO衫 | J37: 面料F03861+21双纱+高弹丝+面料F00370+面料F00371 | L37: 80 | M37: 2026-01-10
A38: 2026年度生产进度 | B38: 季晓芳 | C38: 2025-08-30 | D38: 本村 | E38: LANDWELL | F38: SO250828-429 | G38: CH02-1269 | H38: CH02-1269 | I38: 男士绣花T恤 | J38: 面料F03861+1*1罗文 | L38: 378 | M38: 2026-01-10
A39: 2026年度生产进度 | B39: 季晓芳 | C39: 2025-08-30 | D39: 本村 | E39: LANDWELL | F39: SO250828-430 | G39: CH12-1269 | H39: CH12-1269 | I39: 女士绣花T恤 | J39: 面料F03861+1*1罗文 | L39: 87 | M39: 2026-01-10
A40: 2026年度生产进度 | B40: 季晓芳 | C40: 2025-08-30 | D40: 本村 | E40: LANDWELL | F40: SO250828-431 | G40: CH02-1270 | H40: CH02-1270 | I40: 男士绣花PO衫 | J40: 面料F03861+21支双纱+高弹丝+面料F00372+面料F00373 | L40: 3295 | M40: 2026-01-10
A41: 2026年度生产进度 | B41: 季晓芳 | C41: 2025-08-30 | D41: 本村 | E41: LANDWELL | F41: SO250828-432 | G41: CH12-1270 | H41: CH12-1270 | I41: 女士绣花PO衫 | J41: 面料F03861+21支双纱+高弹丝+面料F00374+面料F00375 | L41: 206 | M41: 2026-01-10
...

Sheet 物料档案
A1: 物料档案 - 纱线 / 面料 / 辅料统一编码 | B1: 物料档案 - 纱线 / 面料 / 辅料统一编码 | C1: 物料档案 - 纱线 / 面料 / 辅料统一编码 | D1: 物料档案 - 纱线 / 面料 / 辅料统一编码 | E1: 物料档案 - 纱线 / 面料 / 辅料统一编码 | F1: 物料档案 - 纱线 / 面料 / 辅料统一编码 | G1: 物料档案 - 纱线 / 面料 / 辅料统一编码 | H1: 物料档案 - 纱线 / 面料 / 辅料统一编码 | I1: 物料档案 - 纱线 / 面料 / 辅料统一编码 | J1: 物料档案 - 纱线 / 面料 / 辅料统一编码 | K1: 物料档案 - 纱线 / 面料 / 辅料统一编码 | L1: 物料档案 - 纱线 / 面料 / 辅料统一编码 | M1: 物料档案 - 纱线 / 面料 / 辅料统一编码
A3: 库存主单位是所有出入库折算后的核算单位；卷、包等非固定单位可在单位换算表维护系数 | B3: 库存主单位是所有出入库折算后的核算单位；卷、包等非固定单位可在单位换算表维护系数 | C3: 库存主单位是所有出入库折算后的核算单位；卷、包等非固定单位可在单位换算表维护系数 | D3: 库存主单位是所有出入库折算后的核算单位；卷、包等非固定单位可在单位换算表维护系数 | E3: 库存主单位是所有出入库折算后的核算单位；卷、包等非固定单位可在单位换算表维护系数 | F3: 库存主单位是所有出入库折算后的核算单位；卷、包等非固定单位可在单位换算表维护系数 | G3: 库存主单位是所有出入库折算后的核算单位；卷、包等非固定单位可在单位换算表维护系数 | H3: 库存主单位是所有出入库折算后的核算单位；卷、包等非固定单位可在单位换算表维护系数 | I3: 库存主单位是所有出入库折算后的核算单位；卷、包等非固定单位可在单位换算表维护系数 | J3: 库存主单位是所有出入库折算后的核算单位；卷、包等非固定单位可在单位换算表维护系数 | K3: 库存主单位是所有出入库折算后的核算单位；卷、包等非固定单位可在单位换算表维护系数 | L3: 库存主单位是所有出入库折算后的核算单位；卷、包等非固定单位可在单位换算表维护系数 | M3: 库存主单位是所有出入库折算后的核算单位；卷、包等非固定单位可在单位换算表维护系数
A4: 物料编码 | B4: 物料名称 | C4: 物料类型 | D4: 规格/纱支/门幅 | E4: 颜色/缸号 | F4: 默认供应商 | G4: 库存主单位 | H4: 安全库存 | I4: 采购提前期(天) | J4: 默认库位 | K4: 状态 | L4: 替代料 | M4: 备注
A5: MAT-0001 | B5: 市场面料格子 | C5: 面料 | G5: M | H5: 80 | I5: 15 | J5: 面料仓-B区 | K5: 启用
A6: MAT-0002 | B6: 150D全涤线 | C6: 纱线 | G6: KG | H6: 30 | I6: 20 | J6: 纱线仓-A区 | K6: 启用
A7: MAT-0003 | B7: 面料F01752 | C7: 面料 | F7: 鸿澄 | G7: M | H7: 80 | I7: 15 | J7: 面料仓-B区 | K7: 启用
A8: MAT-0004 | B8: 面料F05140 | C8: 面料 | F8: 鸿澄 | G8: M | H8: 80 | I8: 15 | J8: 面料仓-B区 | K8: 启用
A9: MAT-0005 | B9: F04595 全涤华夫格 | C9: 面料 | G9: M | H9: 80 | I9: 15 | J9: 面料仓-B区 | K9: 启用
A10: MAT-0006 | B10: F04858全涤螺纹 | C10: 面料 | G10: M | H10: 80 | I10: 15 | J10: 面料仓-B区 | K10: 启用
A11: MAT-0007 | B11: 150D涤丝 | C11: 纱线 | G11: KG | H11: 30 | I11: 20 | J11: 纱线仓-A区 | K11: 启用
A12: MAT-0008 | B12: 150D涤丝 | C12: 纱线 | G12: KG | H12: 30 | I12: 20 | J12: 纱线仓-A区 | K12: 启用
A13: MAT-0009 | B13: F05721 精编空花 | C13: 面料 | G13: M | H13: 80 | I13: 15 | J13: 面料仓-B区 | K13: 启用
A14: MAT-0010 | B14: 客供毛圈 | C14: 纱线 | G14: KG | H14: 30 | I14: 20 | J14: 纱线仓-A区 | K14: 启用
A15: MAT-0011 | B15: 2*2罗文 | C15: 辅料 | G15: PCS | H15: 100 | I15: 10 | J15: 辅料仓-C区 | K15: 启用
A16: MAT-0012 | B16: 20/1汗布 | C16: 面料 | G16: M | H16: 80 | I16: 15 | J16: 面料仓-B区 | K16: 启用
A17: MAT-0013 | B17: F00921 | C17: 面料 | G17: M | H17: 80 | I17: 15 | J17: 面料仓-B区 | K17: 启用
A18: MAT-0014 | B18: 索罗娜罗纹 | C18: 面料 | G18: M | H18: 80 | I18: 15 | J18: 面料仓-B区 | K18: 启用
A19: MAT-0015 | B19: 客供毛圈 | C19: 纱线 | G19: KG | H19: 30 | I19: 20 | J19: 纱线仓-A区 | K19: 启用
A20: MAT-0016 | B20: 网眼袋布 | C20: 面料 | G20: M | H20: 80 | I20: 15 | J20: 面料仓-B区 | K20: 启用
A21: MAT-0017 | B21: 客供毛圈 | C21: 纱线 | G21: KG | H21: 30 | I21: 20 | J21: 纱线仓-A区 | K21: 启用
A22: MAT-0018 | B22: 150D中弹丝 | C22: 纱线 | F22: 奕翔/伟强/恒升 | G22: KG | H22: 30 | I22: 20 | J22: 纱线仓-A区 | K22: 启用
A23: MAT-0019 | B23: 雪尼尔 | C23: 纱线 | F23: 奕翔/伟强/恒升 | G23: KG | H23: 30 | I23: 20 | J23: 纱线仓-A区 | K23: 启用
A24: MAT-0020 | B24: 氨纶丝 | C24: 纱线 | F24: 奕翔/伟强/恒升 | G24: KG | H24: 30 | I24: 20 | J24: 纱线仓-A区 | K24: 启用
A25: MAT-0021 | B25: 240克空气层 | C25: 辅料 | G25: PCS | H25: 100 | I25: 10 | J25: 辅料仓-C区 | K25: 启用
A26: MAT-0022 | B26: 面料F02666 | C26: 面料 | G26: M | H26: 80 | I26: 15 | J26: 面料仓-B区 | K26: 启用
A27: MAT-0023 | B27: 面料F03181 | C27: 面料 | G27: M | H27: 80 | I27: 15 | J27: 面料仓-B区 | K27: 启用
A28: MAT-0024 | B28: 240克棉涤氨纶空气层 | C28: 辅料 | G28: PCS | H28: 100 | I28: 10 | J28: 辅料仓-C区 | K28: 启用
A29: MAT-0025 | B29: 面料F06037 | C29: 面料 | G29: M | H29: 80 | I29: 15 | J29: 面料仓-B区 | K29: 启用
A30: MAT-0026 | B30: 面料F05915 | C30: 面料 | G30: M | H30: 80 | I30: 15 | J30: 面料仓-B区 | K30: 启用
A31: MAT-0027 | B31: 日本别布 | C31: 面料 | G31: M | H31: 80 | I31: 15 | J31: 面料仓-B区 | K31: 启用
A32: MAT-0028 | B32: 2/36麻纱线 | C32: 纱线 | G32: KG | H32: 30 | I32: 20 | J32: 纱线仓-A区 | K32: 启用
A33: MAT-0029 | B33: 2/36麻纱线 | C33: 纱线 | G33: KG | H33: 30 | I33: 20 | J33: 纱线仓-A区 | K33: 启用
A34: MAT-0030 | B34: 2/36麻纱线 | C34: 纱线 | G34: KG | H34: 30 | I34: 20 | J34: 纱线仓-A区 | K34: 启用
A35: MAT-0031 | B35: 2/36麻纱线 | C35: 纱线 | G35: KG | H35: 30 | I35: 20 | J35: 纱线仓-A区 | K35: 启用
A36: MAT-0032 | B36: 2/36麻纱线 | C36: 纱线 | G36: KG | H36: 30 | I36: 20 | J36: 纱线仓-A区 | K36: 启用
... A41: MAT-0037 | B41: 2/36麻纱线 | C41: 纱线 | G41: KG | H41: 30 | I41: 20 | J41: 纱线仓-A区 | K41: 启用
A42: MAT-0038 | B42: 150D全涤线 | C42: 面料 | F42: 恒升 | G42: M | H42: 80 | I42: 15 | J42: 面料仓-B区 | K42: 启用
A43: MAT-0039 | B43: 丝光广东棉毛布 | C43: 纱线 | F43: 恒升 | G43: KG | H43: 30 | I43: 20 | J43: 纱线仓-A区 | K43: 启用
A44: MAT-0040 | B44: 面料F04411 | C44: 面料 | G44: M | H44: 80 | I44: 15 | J44: 面料仓-B区 | K44: 启用
A45: MAT-0041 | B45: 2*2罗文面料 | C45: 面料 | G45: M | H45: 80 | I45: 15 | J45: 面料仓-B区 | K45: 启用
...

Sheet BOM用料
A1: BOM用料 - 订单需求与损耗计算 | B1: BOM用料 - 订单需求与损耗计算 | C1: BOM用料 - 订单需求与损耗计算 | D1: BOM用料 - 订单需求与损耗计算 | E1: BOM用料 - 订单需求与损耗计算 | F1: BOM用料 - 订单需求与损耗计算 | G1: BOM用料 - 订单需求与损耗计算 | H1: BOM用料 - 订单需求与损耗计算 | I1: BOM用料 - 订单需求与损耗计算 | J1: BOM用料 - 订单需求与损耗计算 | K1: BOM用料 - 订单需求与损耗计算 | L1: BOM用料 - 订单需求与损耗计算 | M1: BOM用料 - 订单需求与损耗计算 | N1: BOM用料 - 订单需求与损耗计算 | O1: BOM用料 - 订单需求与损耗计算 | P1: BOM用料 - 订单需求与损耗计算 | Q1: BOM用料 - 订单需求与损耗计算 | R1: BOM用料 - 订单需求与损耗计算
A3: 计划用量 = 订单数量 × 单耗 × (1 + 损耗率)；若源表已有原料数量，可放在“源表需求量”做核对 | B3: 计划用量 = 订单数量 × 单耗 × (1 + 损耗率)；若源表已有原料数量，可放在“源表需求量”做核对 | C3: 计划用量 = 订单数量 × 单耗 × (1 + 损耗率)；若源表已有原料数量，可放在“源表需求量”做核对 | D3: 计划用量 = 订单数量 × 单耗 × (1 + 损耗率)；若源表已有原料数量，可放在“源表需求量”做核对 | E3: 计划用量 = 订单数量 × 单耗 × (1 + 损耗率)；若源表已有原料数量，可放在“源表需求量”做核对 | F3: 计划用量 = 订单数量 × 单耗 × (1 + 损耗率)；若源表已有原料数量，可放在“源表需求量”做核对 | G3: 计划用量 = 订单数量 × 单耗 × (1 + 损耗率)；若源表已有原料数量，可放在“源表需求量”做核对 | H3: 计划用量 = 订单数量 × 单耗 × (1 + 损耗率)；若源表已有原料数量，可放在“源表需求量”做核对 | I3: 计划用量 = 订单数量 × 单耗 × (1 + 损耗率)；若源表已有原料数量，可放在“源表需求量”做核对 | J3: 计划用量 = 订单数量 × 单耗 × (1 + 损耗率)；若源表已有原料数量，可放在“源表需求量”做核对 | K3: 计划用量 = 订单数量 × 单耗 × (1 + 损耗率)；若源表已有原料数量，可放在“源表需求量”做核对 | L3: 计划用量 = 订单数量 × 单耗 × (1 + 损耗率)；若源表已有原料数量，可放在“源表需求量”做核对 | M3: 计划用量 = 订单数量 × 单耗 × (1 + 损耗率)；若源表已有原料数量，可放在“源表需求量”做核对 | N3: 计划用量 = 订单数量 × 单耗 × (1 + 损耗率)；若源表已有原料数量，可放在“源表需求量”做核对 | O3: 计划用量 = 订单数量 × 单耗 × (1 + 损耗率)；若源表已有原料数量，可放在“源表需求量”做核对 | P3: 计划用量 = 订单数量 × 单耗 × (1 + 损耗率)；若源表已有原料数量，可放在“源表需求量”做核对 | Q3: 计划用量 = 订单数量 × 单耗 × (1 + 损耗率)；若源表已有原料数量，可放在“源表需求量”做核对 | R3: 计划用量 = 订单数量 × 单耗 × (1 + 损耗率)；若源表已有原料数量，可放在“源表需求量”做核对
A4: BOM编号 | B4: 合同/销售单号 | C4: 品番 | D4: 款式 | E4: 物料编码 | F4: 物料名称 | G4: 物料类型 | H4: 规格 | I4: 颜色 | J4: 用量单位 | K4: 单耗 | L4: 订单数量 | M4: 损耗率 | N4: 计划用量 | O4: 源表需求量 | P4: 供应商 | Q4: 来源 | R4: 备注
A5: BOM-0001 | B5: 历史订单 | C5: 暂无 | D5: 女士V领针织 | E5: MAT-0001 | F5: 市场面料格子 | G5: 面料 | J5: KG | L5: 695 | M5: 0.05 | N5: =IF(OR(K5="",L5=""),"",K5*L5*(1+M5)) | Q5: 生产进度表拆分 | R5: 示例：素材/数量/单耗含 + 时已拆成多行
A6: BOM-0002 | B6: SO250714-252 | C6: 66SPSM611 | D6: 男士毛衣开衫 | E6: MAT-0002 | F6: 150D全涤线 | G6: 纱线 | J6: KG | K6: 0.33 | L6: 2700 | M6: 0.03 | N6: =IF(OR(K6="",L6=""),"",K6*L6*(1+M6)) -> 917.73 | O6: 980.1 | Q6: 生产进度表拆分 | R6: 示例：素材/数量/单耗含 + 时已拆成多行
A7: BOM-0003 | B7: SO251020-722 | C7: 42-14-0299-639 | D7: 男士针织T恤衫 | E7: MAT-0003 | F7: 面料F01752 | G7: 面料 | J7: M | K7: 0.9 | L7: 2400 | M7: 0.05 | N7: =IF(OR(K7="",L7=""),"",K7*L7*(1+M7)) -> 2268 | O7: 2376 | P7: 鸿澄 | Q7: 生产进度表拆分 | R7: 示例：素材/数量/单耗含 + 时已拆成多行
A8: BOM-0004 | B8: SO251020-722 | C8: 42-14-0299-639 | D8: 男士针织T恤衫 | E8: MAT-0004 | F8: 面料F05140 | G8: 面料 | J8: M | K8: 0.02 | L8: 2400 | M8: 0.05 | N8: =IF(OR(K8="",L8=""),"",K8*L8*(1+M8)) -> 50.4 | O8: 52.8 | P8: 鸿澄 | Q8: 生产进度表拆分 | R8: 示例：素材/数量/单耗含 + 时已拆成多行
A9: BOM-0005 | B9: SO260318-1579 | C9: 12-04-0209-802 | D9: 男士T恤 | E9: MAT-0005 | F9: F04595 全涤华夫格 | G9: 面料 | J9: M | K9: 1.55 | L9: 850 | M9: 0.05 | N9: =IF(OR(K9="",L9=""),"",K9*L9*(1+M9)) -> 1383.375 | O9: 6864 | Q9: 生产进度表拆分 | R9: 示例：素材/数量/单耗含 + 时已拆成多行
A10: BOM-0006 | B10: SO260318-1579 | C10: 12-04-0209-802 | D10: 男士T恤 | E10: MAT-0006 | F10: F04858全涤螺纹 | G10: 面料 | J10: M | K10: 0.04 | L10: 850 | M10: 0.05 | N10: =IF(OR(K10="",L10=""),"",K10*L10*(1+M10)) -> 35.7 | O10: 191 | Q10: 生产进度表拆分 | R10: 示例：素材/数量/单耗含 + 时已拆成多行
A11: BOM-0007 | B11: SO260318-1581 | C11: 11-05-0145-803 | D11: 男士条纹毛衣 | E11: MAT-0007 | F11: 150D涤丝 | G11: 纱线 | J11: KG | K11: 0.14 | L11: 1108 | M11: 0.03 | N11: =IF(OR(K11="",L11=""),"",K11*L11*(1+M11)) -> 159.7736 | O11: 362 | Q11: 生产进度表拆分 | R11: 示例：素材/数量/单耗含 + 时已拆成多行
A12: BOM-0008 | B12: SO260318-1581 | C12: 11-05-0145-803 | D12: 男士条纹毛衣 | E12: MAT-0008 | F12: 150D涤丝 | G12: 纱线 | J12: KG | K12: 0.142 | L12: 1108 | M12: 0.03 | N12: =IF(OR(K12="",L12=""),"",K12*L12*(1+M12)) -> 162.05608 | O12: 362 | Q12: 生产进度表拆分 | R12: 示例：素材/数量/单耗含 + 时已拆成多行
A13: BOM-0009 | B13: SO260318-1590 | C13: 11-13-2266-803 | D13: 男士针织拉链开衫 | E13: MAT-0009 | F13: F05721 精编空花 | G13: 面料 | J13: M | K13: 0.161 | L13: 1628 | M13: 0.05 | N13: =IF(OR(K13="",L13=""),"",K13*L13*(1+M13)) -> 275.2134 | O13: 3027 | Q13: 生产进度表拆分 | R13: 示例：素材/数量/单耗含 + 时已拆成多行
A14: BOM-0010 | B14: SO260318-1577 | C14: 11-13-1661-803 | D14: 男士风帽套头衫 | E14: MAT-0010 | F14: 客供毛圈 | G14: 纱线 | J14: KG | K14: 1.7 | L14: 30 | M14: 0.03 | N14: =IF(OR(K14="",L14=""),"",K14*L14*(1+M14)) -> 52.53 | Q14: 生产进度表拆分 | R14: 示例：素材/数量/单耗含 + 时已拆成多行
A15: BOM-0011 | B15: SO260318-1577 | C15: 11-13-1661-803 | D15: 男士风帽套头衫 | E15: MAT-0011 | F15: 2*2罗文 | G15: 辅料 | J15: KG | K15: 0.26 | L15: 30 | M15: 0.05 | N15: =IF(OR(K15="",L15=""),"",K15*L15*(1+M15)) -> 8.19 | Q15: 生产进度表拆分 | R15: 示例：素材/数量/单耗含 + 时已拆成多行
A16: BOM-0012 | B16: SO260318-1577 | C16: 11-13-1661-803 | D16: 男士风帽套头衫 | E16: MAT-0012 | F16: 20/1汗布 | G16: 面料 | J16: KG | K16: 0.15 | L16: 30 | M16: 0.05 | N16: =IF(OR(K16="",L16=""),"",K16*L16*(1+M16)) -> 4.725 | Q16: 生产进度表拆分 | R16: 示例：素材/数量/单耗含 + 时已拆成多行
A17: BOM-0013 | B17: SO260319-1607 | C17: 6-0086-1-53-201 | D17: 圆领套头衫 | E17: MAT-0013 | F17: F00921 | G17: 面料 | J17: M | K17: 1.1 | L17: 188 | M17: 0.05 | N17: =IF(OR(K17="",L17=""),"",K17*L17*(1+M17)) -> 217.14 | O17: 208 | Q17: 生产进度表拆分
A18: BOM-0014 | B18: SO260319-1607 | C18: 6-0086-1-53-201 | D18: 圆领套头衫 | E18: MAT-0014 | F18: 索罗娜罗纹 | G18: 面料 | J18: M | K18: 0.18 | L18: 188 | M18: 0.05 | N18: =IF(OR(K18="",L18=""),"",K18*L18*(1+M18)) -> 35.532 | O18: 38 | Q18: 生产进度表拆分
A19: BOM-0015 | B19: SO260318-1578 | C19: 11-24-3533-803 | D19: 男士长裤 | E19: MAT-0015 | F19: 客供毛圈 | G19: 纱线 | J19: KG | K19: 1.92 | L19: 30 | M19: 0.03 | N19: =IF(OR(K19="",L19=""),"",K19*L19*(1+M19)) -> 59.328 | Q19: 生产进度表拆分
A20: BOM-0016 | B20: SO260318-1578 | C20: 11-24-3533-803 | D20: 男士长裤 | E20: MAT-0016 | F20: 网眼袋布 | G20: 面料 | J20: KG | K20: 0.26 | L20: 30 | M20: 0.05 | N20: =IF(OR(K20="",L20=""),"",K20*L20*(1+M20)) -> 8.19 | Q20: 生产进度表拆分
A21: BOM-0017 | B21: SO260318-1578 | C21: 11-24-3533-803 | D21: 男士长裤 | E21: MAT-0017 | F21: 客供毛圈 | G21: 纱线 | J21: KG | K21: 0.16 | L21: 30 | M21: 0.03 | N21: =IF(OR(K21="",L21=""),"",K21*L21*(1+M21)) -> 4.944 | Q21: 生产进度表拆分
A22: BOM-0018 | B22: SO251119-995 | C22: 26-080-312-5000-1-0 | D22: 男士毛衣POLO衫 | E22: MAT-0018 | F22: 150D中弹丝 | G22: 纱线 | J22: KG | K22: 0.16 | L22: 300 | M22: 0.03 | N22: =IF(OR(K22="",L22=""),"",K22*L22*(1+M22)) -> 49.44 | O22: 52.16 | P22: 奕翔/伟强/恒升 | Q22: 生产进度表拆分
A23: BOM-0019 | B23: SO251119-995 | C23: 26-080-312-5000-1-0 | D23: 男士毛衣POLO衫 | E23: MAT-0019 | F23: 雪尼尔 | G23: 纱线 | J23: KG | K23: 0.19 | L23: 300 | M23: 0.03 | N23: =IF(OR(K23="",L23=""),"",K23*L23*(1+M23)) -> 58.71 | O23: 123.46 | P23: 奕翔/伟强/恒升 | Q23: 生产进度表拆分
A24: BOM-0020 | B24: SO251119-995 | C24: 26-080-312-5000-1-0 | D24: 男士毛衣POLO衫 | E24: MAT-0020 | F24: 氨纶丝 | G24: 纱线 | J24: KG | K24: 0.02 | L24: 300 | M24: 0.03 | N24: =IF(OR(K24="",L24=""),"",K24*L24*(1+M24)) -> 6.18 | O24: 16.53 | P24: 奕翔/伟强/恒升 | Q24: 生产进度表拆分
A25: BOM-0021 | B25: SO251205-1093 | C25: 616-35027 | D25: 男士针织毛毯针套头衫 | E25: MAT-0021 | F25: 240克空气层 | G25: 辅料 | J25: KG | K25: 0.95 | L25: 750 | M25: 0.05 | N25: =IF(OR(K25="",L25=""),"",K25*L25*(1+M25)) -> 748.125 | O25: 836 | Q25: 生产进度表拆分
A26: BOM-0022 | B26: SO251018-708 | C26: 1612-1-000024 | D26: 女士针织T | E26: MAT-0022 | F26: 面料F02666 | G26: 面料 | J26: M | K26: 0.74 | L26: 1500 | M26: 0.05 | N26: =IF(OR(K26="",L26=""),"",K26*L26*(1+M26)) -> 1165.5 | O26: 1221 | Q26: 生产进度表拆分
A27: BOM-0023 | B27: SO251018-708 | C27: 1612-1-000024 | D27: 女士针织T | E27: MAT-0023 | F27: 面料F03181 | G27: 面料 | J27: M | K27: 0.03 | L27: 1500 | M27: 0.05 | N27: =IF(OR(K27="",L27=""),"",K27*L27*(1+M27)) -> 47.25 | O27: 49.5 | Q27: 生产进度表拆分
A28: BOM-0024 | B28: SO251205-1091 | C28: 616-35026 | D28: 男士针织套头衫 | E28: MAT-0024 | F28: 240克棉涤氨纶空气层 | G28: 辅料 | J28: KG | K28: 0.93 | L28: 2000 | M28: 0.05 | N28: =IF(OR(K28="",L28=""),"",K28*L28*(1+M28)) -> 1953 | O28: 2046 | Q28: 生产进度表拆分
A29: BOM-0025 | B29: SO250806-336 | C29: KKWMLM0333 | D29: 女士针织T恤 | E29: MAT-0025 | F29: 面料F06037 | G29: 面料 | J29: M | K29: 0.75 | L29: 1037 | M29: 0.05 | N29: =IF(OR(K29="",L29=""),"",K29*L29*(1+M29)) -> 816.6375 | O29: 855.51 | Q29: 生产进度表拆分
A30: BOM-0026 | B30: SO250806-338 | C30: KKWMLM0331 | D30: 女士针织套头衫 | E30: MAT-0026 | F30: 面料F05915 | G30: 面料 | J30: M | K30: 0.55 | L30: 628 | M30: 0.05 | N30: =IF(OR(K30="",L30=""),"",K30*L30*(1+M30)) -> 362.67 | O30: 379.95 | Q30: 生产进度表拆分
A31: BOM-0027 | B31: SO250806-338 | C31: KKWMLM0331 | D31: 女士针织套头衫 | E31: MAT-0027 | F31: 日本别布 | G31: 面料 | J31: M | K31: 0.18 | L31: 628 | M31: 0.05 | N31: =IF(OR(K31="",L31=""),"",K31*L31*(1+M31)) -> 118.692 | O31: 124.36 | Q31: 生产进度表拆分
A32: BOM-0028 | B32: SO250809-343 | C32: 102439090005 | D32: 男士毛衣拼接中国结上衣 | E32: MAT-0028 | F32: 2/36麻纱线 | G32: 纱线 | J32: KG | K32: 0.72 | L32: 50 | M32: 0.03 | N32: =IF(OR(K32="",L32=""),"",K32*L32*(1+M32)) -> 37.08 | O32: 40.68 | Q32: 生产进度表拆分
A33: BOM-0029 | B33: SO250809-343 | C33: 102439090005 | D33: 男士毛衣拼接中国结上衣 | E33: MAT-0029 | F33: 2/36麻纱线 | G33: 纱线 | J33: KG | K33: 0.72 | L33: 50 | M33: 0.03 | N33: =IF(OR(K33="",L33=""),"",K33*L33*(1+M33)) -> 37.08 | O33: 0.29 | Q33: 生产进度表拆分
A34: BOM-0030 | B34: SO250811-349 | C34: 102439090006 | D34: 男士毛衣拼接上衣 | E34: MAT-0030 | F34: 2/36麻纱线 | G34: 纱线 | J34: M | K34: 0.955 | L34: 50 | M34: 0.03 | N34: =IF(OR(K34="",L34=""),"",K34*L34*(1+M34)) -> 49.1825 | O34: 36 | Q34: 生产进度表拆分
A35: BOM-0031 | B35: SO250811-349 | C35: 102439090006 | D35: 男士毛衣拼接上衣 | E35: MAT-0031 | F35: 2/36麻纱线 | G35: 纱线 | J35: KG | K35: 0.955 | L35: 50 | M35: 0.03 | N35: =IF(OR(K35="",L35=""),"",K35*L35*(1+M35)) -> 49.1825 | O35: 50 | Q35: 生产进度表拆分
A36: BOM-0032 | B36: SO250811-350 | C36: 1043390900068 | D36: 男士毛衣拼接长裤 | E36: MAT-0032 | F36: 2/36麻纱线 | G36: 纱线 | J36: KG | K36: 0.86 | L36: 50 | M36: 0.03 | N36: =IF(OR(K36="",L36=""),"",K36*L36*(1+M36)) -> 44.29 | O36: 53.96 | Q36: 生产进度表拆分
... A41: BOM-0037 | B41: SO250811-347 | C41: 1080390900003 | D41: 毛衣拼接围巾 | E41: MAT-0037 | F41: 2/36麻纱线 | G41: 纱线 | J41: KG | K41: 0.15 | L41: 50 | M41: 0.03 | N41: =IF(OR(K41="",L41=""),"",K41*L41*(1+M41)) -> 7.725 | O41: 9.04 | Q41: 生产进度表拆分
A42: BOM-0038 | B42: SO251206-1103 | C42: 51P13-713 | D42: 男士针织拼接T恤 | E42: MAT-0038 | F42: 150D全涤线 | G42: 面料 | J42: M | K42: 0.06 | L42: 1400 | M42: 0.05 | N42: =IF(OR(K42="",L42=""),"",K42*L42*(1+M42)) -> 88.2 | O42: 200.2 | P42: 恒升 | Q42: 生产进度表拆分
A43: BOM-0039 | B43: SO251206-1103 | C43: 51P13-713 | D43: 男士针织拼接T恤 | E43: MAT-0039 | F43: 丝光广东棉毛布 | G43: 纱线 | J43: KG | K43: 0.44 | L43: 1400 | M43: 0.03 | N43: =IF(OR(K43="",L43=""),"",K43*L43*(1+M43)) -> 634.48 | O43: 677.6 | P43: 恒升 | Q43: 生产进度表拆分
A44: BOM-0040 | B44: SO250819-379 | C44: 3612-1-000026 | D44: 女士成衣染色套头衫 | E44: MAT-0040 | F44: 面料F04411 | G44: 面料 | J44: M | K44: 0.85 | L44: 2000 | M44: 0.05 | N44: =IF(OR(K44="",L44=""),"",K44*L44*(1+M44)) -> 1785 | O44: 1870 | Q44: 生产进度表拆分
A45: BOM-0041 | B45: SO250819-379 | C45: 3612-1-000026 | D45: 女士成衣染色套头衫 | E45: MAT-0041 | F45: 2*2罗文面料 | G45: 面料 | J45: M | K45: 0.29 | L45: 2000 | M45: 0.05 | N45: =IF(OR(K45="",L45=""),"",K45*L45*(1+M45)) -> 609 | O45: 638 | Q45: 生产进度表拆分
...

Sheet 入库明细
A1: 入库明细 - 采购/退料/调拨/盘盈 | B1: 入库明细 - 采购/退料/调拨/盘盈 | C1: 入库明细 - 采购/退料/调拨/盘盈 | D1: 入库明细 - 采购/退料/调拨/盘盈 | E1: 入库明细 - 采购/退料/调拨/盘盈 | F1: 入库明细 - 采购/退料/调拨/盘盈 | G1: 入库明细 - 采购/退料/调拨/盘盈 | H1: 入库明细 - 采购/退料/调拨/盘盈 | I1: 入库明细 - 采购/退料/调拨/盘盈 | J1: 入库明细 - 采购/退料/调拨/盘盈 | K1: 入库明细 - 采购/退料/调拨/盘盈 | L1: 入库明细 - 采购/退料/调拨/盘盈 | M1: 入库明细 - 采购/退料/调拨/盘盈 | N1: 入库明细 - 采购/退料/调拨/盘盈 | O1: 入库明细 - 采购/退料/调拨/盘盈 | P1: 入库明细 - 采购/退料/调拨/盘盈 | Q1: 入库明细 - 采购/退料/调拨/盘盈 | R1: 入库明细 - 采购/退料/调拨/盘盈
A3: 填原单位和数量，系统按物料档案的库存主单位与单位换算表折算；质检不合格可不计可用库存 | B3: 填原单位和数量，系统按物料档案的库存主单位与单位换算表折算；质检不合格可不计可用库存 | C3: 填原单位和数量，系统按物料档案的库存主单位与单位换算表折算；质检不合格可不计可用库存 | D3: 填原单位和数量，系统按物料档案的库存主单位与单位换算表折算；质检不合格可不计可用库存 | E3: 填原单位和数量，系统按物料档案的库存主单位与单位换算表折算；质检不合格可不计可用库存 | F3: 填原单位和数量，系统按物料档案的库存主单位与单位换算表折算；质检不合格可不计可用库存 | G3: 填原单位和数量，系统按物料档案的库存主单位与单位换算表折算；质检不合格可不计可用库存 | H3: 填原单位和数量，系统按物料档案的库存主单位与单位换算表折算；质检不合格可不计可用库存 | I3: 填原单位和数量，系统按物料档案的库存主单位与单位换算表折算；质检不合格可不计可用库存 | J3: 填原单位和数量，系统按物料档案的库存主单位与单位换算表折算；质检不合格可不计可用库存 | K3: 填原单位和数量，系统按物料档案的库存主单位与单位换算表折算；质检不合格可不计可用库存 | L3: 填原单位和数量，系统按物料档案的库存主单位与单位换算表折算；质检不合格可不计可用库存 | M3: 填原单位和数量，系统按物料档案的库存主单位与单位换算表折算；质检不合格可不计可用库存 | N3: 填原单位和数量，系统按物料档案的库存主单位与单位换算表折算；质检不合格可不计可用库存 | O3: 填原单位和数量，系统按物料档案的库存主单位与单位换算表折算；质检不合格可不计可用库存 | P3: 填原单位和数量，系统按物料档案的库存主单位与单位换算表折算；质检不合格可不计可用库存 | Q3: 填原单位和数量，系统按物料档案的库存主单位与单位换算表折算；质检不合格可不计可用库存 | R3: 填原单位和数量，系统按物料档案的库存主单位与单位换算表折算；质检不合格可不计可用库存
A4: 入库单号 | B4: 入库日期 | C4: 入库类型 | D4: 来源/供应商 | E4: 合同/销售单号 | F4: 品番 | G4: 物料编码 | H4: 物料名称 | I4: 物料类型 | J4: 批次/色号 | K4: 原单位 | L4: 入库数量 | M4: 库存主单位 | N4: 换算系数 | O4: 主单位数量 | P4: 库位 | Q4: 质检状态 | R4: 备注
A5: IN-0001 | B5: 2026-06-16 | C5: 采购入库 | E5: 历史订单 | F5: 暂无 | G5: MAT-0001 | H5: 市场面料格子 | I5: 面料 | K5: KG | M5: M | N5: =IFERROR(_xlfn.XLOOKUP(K5&"|"&M5,单位换算!$C$5:$C$30,单位换算!$D$5:$D$30),1) -> 1 | O5: =IF(L5="","",L5*N5) | P5: 面料仓-B区 | Q5: 待检
A6: IN-0002 | B6: 2026-06-16 | C6: 生产进度到料 | E6: SO250714-252 | F6: 66SPSM611 | G6: MAT-0002 | H6: 150D全涤线 | I6: 纱线 | K6: KG | L6: 980.1 | M6: KG | N6: =IFERROR(_xlfn.XLOOKUP(K6&"|"&M6,单位换算!$C$5:$C$30,单位换算!$D$5:$D$30),1) -> 1 | O6: =IF(L6="","",L6*N6) -> 980.1 | P6: 纱线仓-A区 | Q6: 待检
A7: IN-0003 | B7: 2026-06-16 | C7: 生产进度到料 | D7: 鸿澄 | E7: SO251020-722 | F7: 42-14-0299-639 | G7: MAT-0003 | H7: 面料F01752 | I7: 面料 | K7: M | L7: 2376 | M7: M | N7: =IFERROR(_xlfn.XLOOKUP(K7&"|"&M7,单位换算!$C$5:$C$30,单位换算!$D$5:$D$30),1) -> 1 | O7: =IF(L7="","",L7*N7) -> 2376 | P7: 面料仓-B区 | Q7: 待检
A8: IN-0004 | B8: 2026-06-16 | C8: 采购入库 | D8: 鸿澄 | E8: SO251020-722 | F8: 42-14-0299-639 | G8: MAT-0004 | H8: 面料F05140 | I8: 面料 | K8: M | L8: 52.8 | M8: M | N8: =IFERROR(_xlfn.XLOOKUP(K8&"|"&M8,单位换算!$C$5:$C$30,单位换算!$D$5:$D$30),1) -> 1 | O8: =IF(L8="","",L8*N8) -> 52.8 | P8: 面料仓-B区 | Q8: 待检
A9: IN-0005 | B9: 2026-06-16 | C9: 生产进度到料 | E9: SO260318-1579 | F9: 12-04-0209-802 | G9: MAT-0005 | H9: F04595 全涤华夫格 | I9: 面料 | K9: M | L9: 6864 | M9: M | N9: =IFERROR(_xlfn.XLOOKUP(K9&"|"&M9,单位换算!$C$5:$C$30,单位换算!$D$5:$D$30),1) -> 1 | O9: =IF(L9="","",L9*N9) -> 6864 | P9: 面料仓-B区 | Q9: 待检
A10: IN-0006 | B10: 2026-06-16 | C10: 生产进度到料 | E10: SO260318-1579 | F10: 12-04-0209-802 | G10: MAT-0006 | H10: F04858全涤螺纹 | I10: 面料 | K10: M | L10: 191 | M10: M | N10: =IFERROR(_xlfn.XLOOKUP(K10&"|"&M10,单位换算!$C$5:$C$30,单位换算!$D$5:$D$30),1) -> 1 | O10: =IF(L10="","",L10*N10) -> 191 | P10: 面料仓-B区 | Q10: 待检
A11: IN-0007 | B11: 2026-06-16 | C11: 采购入库 | E11: SO260318-1581 | F11: 11-05-0145-803 | G11: MAT-0007 | H11: 150D涤丝 | I11: 纱线 | K11: KG | L11: 362 | M11: KG | N11: =IFERROR(_xlfn.XLOOKUP(K11&"|"&M11,单位换算!$C$5:$C$30,单位换算!$D$5:$D$30),1) -> 1 | O11: =IF(L11="","",L11*N11) -> 362 | P11: 纱线仓-A区 | Q11: 待检
A12: IN-0008 | B12: 2026-06-16 | C12: 生产进度到料 | E12: SO260318-1581 | F12: 11-05-0145-803 | G12: MAT-0008 | H12: 150D涤丝 | I12: 纱线 | K12: KG | L12: 362 | M12: KG | N12: =IFERROR(_xlfn.XLOOKUP(K12&"|"&M12,单位换算!$C$5:$C$30,单位换算!$D$5:$D$30),1) -> 1 | O12: =IF(L12="","",L12*N12) -> 362 | P12: 纱线仓-A区 | Q12: 待检
A13: IN-0009 | B13: 2026-06-16 | C13: 生产进度到料 | E13: SO260318-1590 | F13: 11-13-2266-803 | G13: MAT-0009 | H13: F05721 精编空花 | I13: 面料 | K13: M | L13: 3027 | M13: M | N13: =IFERROR(_xlfn.XLOOKUP(K13&"|"&M13,单位换算!$C$5:$C$30,单位换算!$D$5:$D$30),1) -> 1 | O13: =IF(L13="","",L13*N13) -> 3027 | P13: 面料仓-B区 | Q13: 待检
A14: IN-0010 | B14: 2026-06-16 | C14: 采购入库 | E14: SO260318-1577 | F14: 11-13-1661-803 | G14: MAT-0010 | H14: 客供毛圈 | I14: 纱线 | K14: KG | L14: 51 | M14: KG | N14: =IFERROR(_xlfn.XLOOKUP(K14&"|"&M14,单位换算!$C$5:$C$30,单位换算!$D$5:$D$30),1) -> 1 | O14: =IF(L14="","",L14*N14) -> 51 | P14: 纱线仓-A区 | Q14: 待检
A15: IN-0011 | B15: 2026-06-16 | C15: 生产进度到料 | E15: SO260318-1577 | F15: 11-13-1661-803 | G15: MAT-0011 | H15: 2*2罗文 | I15: 辅料 | K15: KG | L15: 7.8 | M15: PCS | N15: =IFERROR(_xlfn.XLOOKUP(K15&"|"&M15,单位换算!$C$5:$C$30,单位换算!$D$5:$D$30),1) -> 1 | O15: =IF(L15="","",L15*N15) -> 7.8 | P15: 辅料仓-C区 | Q15: 待检
A16: IN-0012 | B16: 2026-06-16 | C16: 生产进度到料 | E16: SO260318-1577 | F16: 11-13-1661-803 | G16: MAT-0012 | H16: 20/1汗布 | I16: 面料 | K16: KG | L16: 4.5 | M16: M | N16: =IFERROR(_xlfn.XLOOKUP(K16&"|"&M16,单位换算!$C$5:$C$30,单位换算!$D$5:$D$30),1) -> 1 | O16: =IF(L16="","",L16*N16) -> 4.5 | P16: 面料仓-B区 | Q16: 待检
A17: IN-0013 | B17: 2026-06-16 | C17: 采购入库 | E17: SO260319-1607 | F17: 6-0086-1-53-201 | G17: MAT-0013 | H17: F00921 | I17: 面料 | K17: M | L17: 208 | M17: M | N17: =IFERROR(_xlfn.XLOOKUP(K17&"|"&M17,单位换算!$C$5:$C$30,单位换算!$D$5:$D$30),1) -> 1 | O17: =IF(L17="","",L17*N17) -> 208 | P17: 面料仓-B区 | Q17: 待检
A18: IN-0014 | B18: 2026-06-16 | C18: 生产进度到料 | E18: SO260319-1607 | F18: 6-0086-1-53-201 | G18: MAT-0014 | H18: 索罗娜罗纹 | I18: 面料 | K18: M | L18: 38 | M18: M | N18: =IFERROR(_xlfn.XLOOKUP(K18&"|"&M18,单位换算!$C$5:$C$30,单位换算!$D$5:$D$30),1) -> 1 | O18: =IF(L18="","",L18*N18) -> 38 | P18: 面料仓-B区 | Q18: 待检
A19: IN-0015 | B19: 2026-06-16 | C19: 生产进度到料 | E19: SO260318-1578 | F19: 11-24-3533-803 | G19: MAT-0015 | H19: 客供毛圈 | I19: 纱线 | K19: KG | L19: 57.6 | M19: KG | N19: =IFERROR(_xlfn.XLOOKUP(K19&"|"&M19,单位换算!$C$5:$C$30,单位换算!$D$5:$D$30),1) -> 1 | O19: =IF(L19="","",L19*N19) -> 57.6 | P19: 纱线仓-A区 | Q19: 待检
A20: IN-0016 | B20: 2026-06-16 | C20: 采购入库 | E20: SO260318-1578 | F20: 11-24-3533-803 | G20: MAT-0016 | H20: 网眼袋布 | I20: 面料 | K20: KG | L20: 7.8 | M20: M | N20: =IFERROR(_xlfn.XLOOKUP(K20&"|"&M20,单位换算!$C$5:$C$30,单位换算!$D$5:$D$30),1) -> 1 | O20: =IF(L20="","",L20*N20) -> 7.8 | P20: 面料仓-B区 | Q20: 待检
A21: IN-0017 | B21: 2026-06-16 | C21: 生产进度到料 | E21: SO260318-1578 | F21: 11-24-3533-803 | G21: MAT-0017 | H21: 客供毛圈 | I21: 纱线 | K21: KG | L21: 4.8 | M21: KG | N21: =IFERROR(_xlfn.XLOOKUP(K21&"|"&M21,单位换算!$C$5:$C$30,单位换算!$D$5:$D$30),1) -> 1 | O21: =IF(L21="","",L21*N21) -> 4.8 | P21: 纱线仓-A区 | Q21: 待检
A22: IN-0018 | B22: 2026-06-16 | C22: 生产进度到料 | D22: 奕翔/伟强/恒升 | E22: SO251119-995 | F22: 26-080-312-5000-1-0 | G22: MAT-0018 | H22: 150D中弹丝 | I22: 纱线 | K22: KG | L22: 52.16 | M22: KG | N22: =IFERROR(_xlfn.XLOOKUP(K22&"|"&M22,单位换算!$C$5:$C$30,单位换算!$D$5:$D$30),1) -> 1 | O22: =IF(L22="","",L22*N22) -> 52.16 | P22: 纱线仓-A区 | Q22: 待检
A23: IN-0019 | B23: 2026-06-16 | C23: 采购入库 | D23: 奕翔/伟强/恒升 | E23: SO251119-995 | F23: 26-080-312-5000-1-0 | G23: MAT-0019 | H23: 雪尼尔 | I23: 纱线 | K23: KG | L23: 123.46 | M23: KG | N23: =IFERROR(_xlfn.XLOOKUP(K23&"|"&M23,单位换算!$C$5:$C$30,单位换算!$D$5:$D$30),1) -> 1 | O23: =IF(L23="","",L23*N23) -> 123.46 | P23: 纱线仓-A区 | Q23: 待检
A24: IN-0020 | B24: 2026-06-16 | C24: 生产进度到料 | D24: 奕翔/伟强/恒升 | E24: SO251119-995 | F24: 26-080-312-5000-1-0 | G24: MAT-0020 | H24: 氨纶丝 | I24: 纱线 | K24: KG | L24: 16.53 | M24: KG | N24: =IFERROR(_xlfn.XLOOKUP(K24&"|"&M24,单位换算!$C$5:$C$30,单位换算!$D$5:$D$30),1) -> 1 | O24: =IF(L24="","",L24*N24) -> 16.53 | P24: 纱线仓-A区 | Q24: 待检
N25: =IFERROR(_xlfn.XLOOKUP(K25&"|"&M25,单位换算!$C$5:$C$30,单位换算!$D$5:$D$30),1) -> 1 | O25: =IF(L25="","",L25*N25)
N26: =IFERROR(_xlfn.XLOOKUP(K26&"|"&M26,单位换算!$C$5:$C$30,单位换算!$D$5:$D$30),1) -> 1 | O26: =IF(L26="","",L26*N26)
N27: =IFERROR(_xlfn.XLOOKUP(K27&"|"&M27,单位换算!$C$5:$C$30,单位换算!$D$5:$D$30),1) -> 1 | O27: =IF(L27="","",L27*N27)
N28: =IFERROR(_xlfn.XLOOKUP(K28&"|"&M28,单位换算!$C$5:$C$30,单位换算!$D$5:$D$30),1) -> 1 | O28: =IF(L28="","",L28*N28)
N29: =IFERROR(_xlfn.XLOOKUP(K29&"|"&M29,单位换算!$C$5:$C$30,单位换算!$D$5:$D$30),1) -> 1 | O29: =IF(L29="","",L29*N29)
N30: =IFERROR(_xlfn.XLOOKUP(K30&"|"&M30,单位换算!$C$5:$C$30,单位换算!$D$5:$D$30),1) -> 1 | O30: =IF(L30="","",L30*N30)
N31: =IFERROR(_xlfn.XLOOKUP(K31&"|"&M31,单位换算!$C$5:$C$30,单位换算!$D$5:$D$30),1) -> 1 | O31: =IF(L31="","",L31*N31)
N32: =IFERROR(_xlfn.XLOOKUP(K32&"|"&M32,单位换算!$C$5:$C$30,单位换算!$D$5:$D$30),1) -> 1 | O32: =IF(L32="","",L32*N32)
N33: =IFERROR(_xlfn.XLOOKUP(K33&"|"&M33,单位换算!$C$5:$C$30,单位换算!$D$5:$D$30),1) -> 1 | O33: =IF(L33="","",L33*N33)
N34: =IFERROR(_xlfn.XLOOKUP(K34&"|"&M34,单位换算!$C$5:$C$30,单位换算!$D$5:$D$30),1) -> 1 | O34: =IF(L34="","",L34*N34)
N35: =IFERROR(_xlfn.XLOOKUP(K35&"|"&M35,单位换算!$C$5:$C$30,单位换算!$D$5:$D$30),1) -> 1 | O35: =IF(L35="","",L35*N35)
N36: =IFERROR(_xlfn.XLOOKUP(K36&"|"&M36,单位换算!$C$5:$C$30,单位换算!$D$5:$D$30),1) -> 1 | O36: =IF(L36="","",L36*N36)
... N204: =IFERROR(_xlfn.XLOOKUP(K204&"|"&M204,单位换算!$C$5:$C$30,单位换算!$D$5:$D$30),1) -> 1 | O204: =IF(L204="","",L204*N204)

Sheet 出库明细
A1: 出库明细 - 横机 / 裁剪 / 缝制 / 后道领料 | B1: 出库明细 - 横机 / 裁剪 / 缝制 / 后道领料 | C1: 出库明细 - 横机 / 裁剪 / 缝制 / 后道领料 | D1: 出库明细 - 横机 / 裁剪 / 缝制 / 后道领料 | E1: 出库明细 - 横机 / 裁剪 / 缝制 / 后道领料 | F1: 出库明细 - 横机 / 裁剪 / 缝制 / 后道领料 | G1: 出库明细 - 横机 / 裁剪 / 缝制 / 后道领料 | H1: 出库明细 - 横机 / 裁剪 / 缝制 / 后道领料 | I1: 出库明细 - 横机 / 裁剪 / 缝制 / 后道领料 | J1: 出库明细 - 横机 / 裁剪 / 缝制 / 后道领料 | K1: 出库明细 - 横机 / 裁剪 / 缝制 / 后道领料 | L1: 出库明细 - 横机 / 裁剪 / 缝制 / 后道领料 | M1: 出库明细 - 横机 / 裁剪 / 缝制 / 后道领料 | N1: 出库明细 - 横机 / 裁剪 / 缝制 / 后道领料 | O1: 出库明细 - 横机 / 裁剪 / 缝制 / 后道领料 | P1: 出库明细 - 横机 / 裁剪 / 缝制 / 后道领料 | Q1: 出库明细 - 横机 / 裁剪 / 缝制 / 后道领料 | R1: 出库明细 - 横机 / 裁剪 / 缝制 / 后道领料
A3: 按工序登记领料；纱线多为横机领料，面料多为裁剪领料，辅料多为缝制/后道领料 | B3: 按工序登记领料；纱线多为横机领料，面料多为裁剪领料，辅料多为缝制/后道领料 | C3: 按工序登记领料；纱线多为横机领料，面料多为裁剪领料，辅料多为缝制/后道领料 | D3: 按工序登记领料；纱线多为横机领料，面料多为裁剪领料，辅料多为缝制/后道领料 | E3: 按工序登记领料；纱线多为横机领料，面料多为裁剪领料，辅料多为缝制/后道领料 | F3: 按工序登记领料；纱线多为横机领料，面料多为裁剪领料，辅料多为缝制/后道领料 | G3: 按工序登记领料；纱线多为横机领料，面料多为裁剪领料，辅料多为缝制/后道领料 | H3: 按工序登记领料；纱线多为横机领料，面料多为裁剪领料，辅料多为缝制/后道领料 | I3: 按工序登记领料；纱线多为横机领料，面料多为裁剪领料，辅料多为缝制/后道领料 | J3: 按工序登记领料；纱线多为横机领料，面料多为裁剪领料，辅料多为缝制/后道领料 | K3: 按工序登记领料；纱线多为横机领料，面料多为裁剪领料，辅料多为缝制/后道领料 | L3: 按工序登记领料；纱线多为横机领料，面料多为裁剪领料，辅料多为缝制/后道领料 | M3: 按工序登记领料；纱线多为横机领料，面料多为裁剪领料，辅料多为缝制/后道领料 | N3: 按工序登记领料；纱线多为横机领料，面料多为裁剪领料，辅料多为缝制/后道领料 | O3: 按工序登记领料；纱线多为横机领料，面料多为裁剪领料，辅料多为缝制/后道领料 | P3: 按工序登记领料；纱线多为横机领料，面料多为裁剪领料，辅料多为缝制/后道领料 | Q3: 按工序登记领料；纱线多为横机领料，面料多为裁剪领料，辅料多为缝制/后道领料 | R3: 按工序登记领料；纱线多为横机领料，面料多为裁剪领料，辅料多为缝制/后道领料
A4: 出库单号 | B4: 出库日期 | C4: 领用工序 | D4: 去向/工厂 | E4: 合同/销售单号 | F4: 品番 | G4: 物料编码 | H4: 物料名称 | I4: 物料类型 | J4: 批次/色号 | K4: 原单位 | L4: 出库数量 | M4: 库存主单位 | N4: 换算系数 | O4: 主单位数量 | P4: 用途/裁片/床次 | Q4: 负责人 | R4: 备注
A5: OUT-0001 | B5: 2026-06-16 | C5: 横机领料 | D5: 横机车间 | E5: 历史订单 | F5: 暂无 | G5: MAT-0001 | H5: 市场面料格子 | I5: 面料 | K5: KG | M5: M | N5: =IFERROR(_xlfn.XLOOKUP(K5&"|"&M5,单位换算!$C$5:$C$30,单位换算!$D$5:$D$30),1) -> 1 | O5: =IF(L5="","",L5*N5) | P5: 按订单领料
A6: OUT-0002 | B6: 2026-06-16 | C6: 裁剪领料 | D6: 裁剪/缝制车间 | E6: SO250714-252 | F6: 66SPSM611 | G6: MAT-0002 | H6: 150D全涤线 | I6: 纱线 | K6: KG | L6: 400.95 | M6: KG | N6: =IFERROR(_xlfn.XLOOKUP(K6&"|"&M6,单位换算!$C$5:$C$30,单位换算!$D$5:$D$30),1) -> 1 | O6: =IF(L6="","",L6*N6) -> 400.95 | P6: 裁片/辅料领用
A7: OUT-0003 | B7: 2026-06-16 | C7: 缝制辅料 | D7: 横机车间 | E7: SO251020-722 | F7: 42-14-0299-639 | G7: MAT-0003 | H7: 面料F01752 | I7: 面料 | K7: M | L7: 972 | M7: M | N7: =IFERROR(_xlfn.XLOOKUP(K7&"|"&M7,单位换算!$C$5:$C$30,单位换算!$D$5:$D$30),1) -> 1 | O7: =IF(L7="","",L7*N7) -> 972 | P7: 按订单领料
A8: OUT-0004 | B8: 2026-06-16 | C8: 后道领料 | D8: 裁剪/缝制车间 | E8: SO251020-722 | F8: 42-14-0299-639 | G8: MAT-0004 | H8: 面料F05140 | I8: 面料 | K8: M | L8: 21.6 | M8: M | N8: =IFERROR(_xlfn.XLOOKUP(K8&"|"&M8,单位换算!$C$5:$C$30,单位换算!$D$5:$D$30),1) -> 1 | O8: =IF(L8="","",L8*N8) -> 21.6 | P8: 裁片/辅料领用
A9: OUT-0005 | B9: 2026-06-16 | C9: 样衣领料 | D9: 横机车间 | E9: SO260318-1579 | F9: 12-04-0209-802 | G9: MAT-0005 | H9: F04595 全涤华夫格 | I9: 面料 | K9: M | L9: 592.875 | M9: M | N9: =IFERROR(_xlfn.XLOOKUP(K9&"|"&M9,单位换算!$C$5:$C$30,单位换算!$D$5:$D$30),1) -> 1 | O9: =IF(L9="","",L9*N9) -> 592.875 | P9: 按订单领料
A10: OUT-0006 | B10: 2026-06-16 | C10: 横机领料 | D10: 裁剪/缝制车间 | E10: SO260318-1579 | F10: 12-04-0209-802 | G10: MAT-0006 | H10: F04858全涤螺纹 | I10: 面料 | K10: M | L10: 15.3 | M10: M | N10: =IFERROR(_xlfn.XLOOKUP(K10&"|"&M10,单位换算!$C$5:$C$30,单位换算!$D$5:$D$30),1) -> 1 | O10: =IF(L10="","",L10*N10) -> 15.3 | P10: 裁片/辅料领用
A11: OUT-0007 | B11: 2026-06-16 | C11: 裁剪领料 | D11: 横机车间 | E11: SO260318-1581 | F11: 11-05-0145-803 | G11: MAT-0007 | H11: 150D涤丝 | I11: 纱线 | K11: KG | L11: 69.804 | M11: KG | N11: =IFERROR(_xlfn.XLOOKUP(K11&"|"&M11,单位换算!$C$5:$C$30,单位换算!$D$5:$D$30),1) -> 1 | O11: =IF(L11="","",L11*N11) -> 69.804 | P11: 按订单领料
A12: OUT-0008 | B12: 2026-06-16 | C12: 缝制辅料 | D12: 裁剪/缝制车间 | E12: SO260318-1581 | F12: 11-05-0145-803 | G12: MAT-0008 | H12: 150D涤丝 | I12: 纱线 | K12: KG | L12: 70.801 | M12: KG | N12: =IFERROR(_xlfn.XLOOKUP(K12&"|"&M12,单位换算!$C$5:$C$30,单位换算!$D$5:$D$30),1) -> 1 | O12: =IF(L12="","",L12*N12) -> 70.801 | P12: 裁片/辅料领用
A13: OUT-0009 | B13: 2026-06-16 | C13: 后道领料 | D13: 横机车间 | E13: SO260318-1590 | F13: 11-13-2266-803 | G13: MAT-0009 | H13: F05721 精编空花 | I13: 面料 | K13: M | L13: 117.949 | M13: M | N13: =IFERROR(_xlfn.XLOOKUP(K13&"|"&M13,单位换算!$C$5:$C$30,单位换算!$D$5:$D$30),1) -> 1 | O13: =IF(L13="","",L13*N13) -> 117.949 | P13: 按订单领料
A14: OUT-0010 | B14: 2026-06-16 | C14: 样衣领料 | D14: 裁剪/缝制车间 | E14: SO260318-1577 | F14: 11-13-1661-803 | G14: MAT-0010 | H14: 客供毛圈 | I14: 纱线 | K14: KG | L14: 22.95 | M14: KG | N14: =IFERROR(_xlfn.XLOOKUP(K14&"|"&M14,单位换算!$C$5:$C$30,单位换算!$D$5:$D$30),1) -> 1 | O14: =IF(L14="","",L14*N14) -> 22.95 | P14: 裁片/辅料领用
A15: OUT-0011 | B15: 2026-06-16 | C15: 横机领料 | D15: 横机车间 | E15: SO260318-1577 | F15: 11-13-1661-803 | G15: MAT-0011 | H15: 2*2罗文 | I15: 辅料 | K15: KG | L15: 3.51 | M15: PCS | N15: =IFERROR(_xlfn.XLOOKUP(K15&"|"&M15,单位换算!$C$5:$C$30,单位换算!$D$5:$D$30),1) -> 1 | O15: =IF(L15="","",L15*N15) -> 3.51 | P15: 按订单领料
A16: OUT-0012 | B16: 2026-06-16 | C16: 裁剪领料 | D16: 裁剪/缝制车间 | E16: SO260318-1577 | F16: 11-13-1661-803 | G16: MAT-0012 | H16: 20/1汗布 | I16: 面料 | K16: KG | L16: 2.025 | M16: M | N16: =IFERROR(_xlfn.XLOOKUP(K16&"|"&M16,单位换算!$C$5:$C$30,单位换算!$D$5:$D$30),1) -> 1 | O16: =IF(L16="","",L16*N16) -> 2.025 | P16: 裁片/辅料领用
A17: OUT-0013 | B17: 2026-06-16 | C17: 缝制辅料 | D17: 横机车间 | E17: SO260319-1607 | F17: 6-0086-1-53-201 | G17: MAT-0013 | H17: F00921 | I17: 面料 | K17: M | L17: 93.06 | M17: M | N17: =IFERROR(_xlfn.XLOOKUP(K17&"|"&M17,单位换算!$C$5:$C$30,单位换算!$D$5:$D$30),1) -> 1 | O17: =IF(L17="","",L17*N17) -> 93.06 | P17: 按订单领料
... A22: OUT-0018 | B22: 2026-06-16 | C22: 缝制辅料 | D22: 裁剪/缝制车间 | E22: SO251119-995 | F22: 26-080-312-5000-1-0 | G22: MAT-0018 | H22: 150D中弹丝 | I22: 纱线 | K22: KG | L22: 21.6 | M22: KG | N22: =IFERROR(_xlfn.XLOOKUP(K22&"|"&M22,单位换算!$C$5:$C$30,单位换算!$D$5:$D$30),1) -> 1 | O22: =IF(L22="","",L22*N22) -> 21.6 | P22: 裁片/辅料领用
N23: =IFERROR(_xlfn.XLOOKUP(K23&"|"&M23,单位换算!$C$5:$C$30,单位换算!$D$5:$D$30),1) -> 1 | O23: =IF(L23="","",L23*N23)
N24: =IFERROR(_xlfn.XLOOKUP(K24&"|"&M24,单位换算!$C$5:$C$30,单位换算!$D$5:$D$30),1) -> 1 | O24: =IF(L24="","",L24*N24)
N25: =IFERROR(_xlfn.XLOOKUP(K25&"|"&M25,单位换算!$C$5:$C$30,单位换算!$D$5:$D$30),1) -> 1 | O25: =IF(L25="","",L25*N25)
N26: =IFERROR(_xlfn.XLOOKUP(K26&"|"&M26,单位换算!$C$5:$C$30,单位换算!$D$5:$D$30),1) -> 1 | O26: =IF(L26="","",L26*N26)
N27: =IFERROR(_xlfn.XLOOKUP(K27&"|"&M27,单位换算!$C$5:$C$30,单位换算!$D$5:$D$30),1) -> 1 | O27: =IF(L27="","",L27*N27)
N28: =IFERROR(_xlfn.XLOOKUP(K28&"|"&M28,单位换算!$C$5:$C$30,单位换算!$D$5:$D$30),1) -> 1 | O28: =IF(L28="","",L28*N28)
N29: =IFERROR(_xlfn.XLOOKUP(K29&"|"&M29,单位换算!$C$5:$C$30,单位换算!$D$5:$D$30),1) -> 1 | O29: =IF(L29="","",L29*N29)
N30: =IFERROR(_xlfn.XLOOKUP(K30&"|"&M30,单位换算!$C$5:$C$30,单位换算!$D$5:$D$30),1) -> 1 | O30: =IF(L30="","",L30*N30)
N31: =IFERROR(_xlfn.XLOOKUP(K31&"|"&M31,单位换算!$C$5:$C$30,单位换算!$D$5:$D$30),1) -> 1 | O31: =IF(L31="","",L31*N31)
N32: =IFERROR(_xlfn.XLOOKUP(K32&"|"&M32,单位换算!$C$5:$C$30,单位换算!$D$5:$D$30),1) -> 1 | O32: =IF(L32="","",L32*N32)
N33: =IFERROR(_xlfn.XLOOKUP(K33&"|"&M33,单位换算!$C$5:$C$30,单位换算!$D$5:$D$30),1) -> 1 | O33: =IF(L33="","",L33*N33)
N34: =IFERROR(_xlfn.XLOOKUP(K34&"|"&M34,单位换算!$C$5:$C$30,单位换算!$D$5:$D$30),1) -> 1 | O34: =IF(L34="","",L34*N34)
... N204: =IFERROR(_xlfn.XLOOKUP(K204&"|"&M204,单位换算!$C$5:$C$30,单位换算!$D$5:$D$30),1) -> 1 | O204: =IF(L204="","",L204*N204)

Sheet 库存总账
A1: 库存总账 - 自动汇总库存、订单需求和预警 | B1: 库存总账 - 自动汇总库存、订单需求和预警 | C1: 库存总账 - 自动汇总库存、订单需求和预警 | D1: 库存总账 - 自动汇总库存、订单需求和预警 | E1: 库存总账 - 自动汇总库存、订单需求和预警 | F1: 库存总账 - 自动汇总库存、订单需求和预警 | G1: 库存总账 - 自动汇总库存、订单需求和预警 | H1: 库存总账 - 自动汇总库存、订单需求和预警 | I1: 库存总账 - 自动汇总库存、订单需求和预警 | J1: 库存总账 - 自动汇总库存、订单需求和预警 | K1: 库存总账 - 自动汇总库存、订单需求和预警 | L1: 库存总账 - 自动汇总库存、订单需求和预警 | M1: 库存总账 - 自动汇总库存、订单需求和预警 | N1: 库存总账 - 自动汇总库存、订单需求和预警 | O1: 库存总账 - 自动汇总库存、订单需求和预警
A3: 可用库存 = 合格入库 - 出库；预警综合负库存、安全库存、订单缺料和采购提前期 | B3: 可用库存 = 合格入库 - 出库；预警综合负库存、安全库存、订单缺料和采购提前期 | C3: 可用库存 = 合格入库 - 出库；预警综合负库存、安全库存、订单缺料和采购提前期 | D3: 可用库存 = 合格入库 - 出库；预警综合负库存、安全库存、订单缺料和采购提前期 | E3: 可用库存 = 合格入库 - 出库；预警综合负库存、安全库存、订单缺料和采购提前期 | F3: 可用库存 = 合格入库 - 出库；预警综合负库存、安全库存、订单缺料和采购提前期 | G3: 可用库存 = 合格入库 - 出库；预警综合负库存、安全库存、订单缺料和采购提前期 | H3: 可用库存 = 合格入库 - 出库；预警综合负库存、安全库存、订单缺料和采购提前期 | I3: 可用库存 = 合格入库 - 出库；预警综合负库存、安全库存、订单缺料和采购提前期 | J3: 可用库存 = 合格入库 - 出库；预警综合负库存、安全库存、订单缺料和采购提前期 | K3: 可用库存 = 合格入库 - 出库；预警综合负库存、安全库存、订单缺料和采购提前期 | L3: 可用库存 = 合格入库 - 出库；预警综合负库存、安全库存、订单缺料和采购提前期 | M3: 可用库存 = 合格入库 - 出库；预警综合负库存、安全库存、订单缺料和采购提前期 | N3: 可用库存 = 合格入库 - 出库；预警综合负库存、安全库存、订单缺料和采购提前期 | O3: 可用库存 = 合格入库 - 出库；预警综合负库存、安全库存、订单缺料和采购提前期
A4: 物料编码 | B4: 物料名称 | C4: 物料类型 | D4: 库存主单位 | E4: 安全库存 | F4: 订单需求 | G4: 合格入库 | H4: 已出库 | I4: 账面库存 | J4: 可用缺口 | K4: 预警状态 | L4: 建议补货量 | M4: 采购提前期(天) | N4: 库位 | O4: 默认供应商
A5: MAT-0001 | B5: 市场面料格子 | C5: 面料 | D5: M | E5: 80 | F5: =SUMIFS(BOM用料!$N$5:$N$244,BOM用料!$E$5:$E$244,A5) -> 0 | G5: =SUMIFS(入库明细!$O$5:$O$204,入库明细!$G$5:$G$204,A5,入库明细!$Q$5:$Q$204,"<>不合格",入库明细!$Q$5:$Q$204,"<>退货") -> 0 | H5: =SUMIFS(出库明细!$O$5:$O$204,出库明细!$G$5:$G$204,A5) -> 0 | I5: =G5-H5 -> 0 | J5: =I5-F5 -> 0 | K5: =IF(I5<0,"负库存",IF(I5<E5,"低于安全库存",IF(J5<0,"订单缺料","正常"))) -> 低于安全库存 | L5: =IF(K5="正常",0,MAX(E5+F5-I5,0)) -> 80 | M5: 15 | N5: 面料仓-B区
A6: MAT-0002 | B6: 150D全涤线 | C6: 纱线 | D6: KG | E6: 30 | F6: =SUMIFS(BOM用料!$N$5:$N$244,BOM用料!$E$5:$E$244,A6) -> 917.73 | G6: =SUMIFS(入库明细!$O$5:$O$204,入库明细!$G$5:$G$204,A6,入库明细!$Q$5:$Q$204,"<>不合格",入库明细!$Q$5:$Q$204,"<>退货") -> 980.1 | H6: =SUMIFS(出库明细!$O$5:$O$204,出库明细!$G$5:$G$204,A6) -> 400.95 | I6: =G6-H6 -> 579.15 | J6: =I6-F6 -> -338.58 | K6: =IF(I6<0,"负库存",IF(I6<E6,"低于安全库存",IF(J6<0,"订单缺料","正常"))) -> 订单缺料 | L6: =IF(K6="正常",0,MAX(E6+F6-I6,0)) -> 368.58 | M6: 20 | N6: 纱线仓-A区
A7: MAT-0003 | B7: 面料F01752 | C7: 面料 | D7: M | E7: 80 | F7: =SUMIFS(BOM用料!$N$5:$N$244,BOM用料!$E$5:$E$244,A7) -> 2268 | G7: =SUMIFS(入库明细!$O$5:$O$204,入库明细!$G$5:$G$204,A7,入库明细!$Q$5:$Q$204,"<>不合格",入库明细!$Q$5:$Q$204,"<>退货") -> 2376 | H7: =SUMIFS(出库明细!$O$5:$O$204,出库明细!$G$5:$G$204,A7) -> 972 | I7: =G7-H7 -> 1404 | J7: =I7-F7 -> -864 | K7: =IF(I7<0,"负库存",IF(I7<E7,"低于安全库存",IF(J7<0,"订单缺料","正常"))) -> 订单缺料 | L7: =IF(K7="正常",0,MAX(E7+F7-I7,0)) -> 944 | M7: 15 | N7: 面料仓-B区 | O7: 鸿澄
A8: MAT-0004 | B8: 面料F05140 | C8: 面料 | D8: M | E8: 80 | F8: =SUMIFS(BOM用料!$N$5:$N$244,BOM用料!$E$5:$E$244,A8) -> 50.4 | G8: =SUMIFS(入库明细!$O$5:$O$204,入库明细!$G$5:$G$204,A8,入库明细!$Q$5:$Q$204,"<>不合格",入库明细!$Q$5:$Q$204,"<>退货") -> 52.8 | H8: =SUMIFS(出库明细!$O$5:$O$204,出库明细!$G$5:$G$204,A8) -> 21.6 | I8: =G8-H8 -> 31.2 | J8: =I8-F8 -> -19.2 | K8: =IF(I8<0,"负库存",IF(I8<E8,"低于安全库存",IF(J8<0,"订单缺料","正常"))) -> 低于安全库存 | L8: =IF(K8="正常",0,MAX(E8+F8-I8,0)) -> 99.2 | M8: 15 | N8: 面料仓-B区 | O8: 鸿澄
A9: MAT-0005 | B9: F04595 全涤华夫格 | C9: 面料 | D9: M | E9: 80 | F9: =SUMIFS(BOM用料!$N$5:$N$244,BOM用料!$E$5:$E$244,A9) -> 1383.375 | G9: =SUMIFS(入库明细!$O$5:$O$204,入库明细!$G$5:$G$204,A9,入库明细!$Q$5:$Q$204,"<>不合格",入库明细!$Q$5:$Q$204,"<>退货") -> 6864 | H9: =SUMIFS(出库明细!$O$5:$O$204,出库明细!$G$5:$G$204,A9) -> 592.875 | I9: =G9-H9 -> 6271.125 | J9: =I9-F9 -> 4887.75 | K9: =IF(I9<0,"负库存",IF(I9<E9,"低于安全库存",IF(J9<0,"订单缺料","正常"))) -> 正常 | L9: =IF(K9="正常",0,MAX(E9+F9-I9,0)) -> 0 | M9: 15 | N9: 面料仓-B区
A10: MAT-0006 | B10: F04858全涤螺纹 | C10: 面料 | D10: M | E10: 80 | F10: =SUMIFS(BOM用料!$N$5:$N$244,BOM用料!$E$5:$E$244,A10) -> 35.7 | G10: =SUMIFS(入库明细!$O$5:$O$204,入库明细!$G$5:$G$204,A10,入库明细!$Q$5:$Q$204,"<>不合格",入库明细!$Q$5:$Q$204,"<>退货") -> 191 | H10: =SUMIFS(出库明细!$O$5:$O$204,出库明细!$G$5:$G$204,A10) -> 15.3 | I10: =G10-H10 -> 175.7 | J10: =I10-F10 -> 140 | K10: =IF(I10<0,"负库存",IF(I10<E10,"低于安全库存",IF(J10<0,"订单缺料","正常"))) -> 正常 | L10: =IF(K10="正常",0,MAX(E10+F10-I10,0)) -> 0 | M10: 15 | N10: 面料仓-B区
A11: MAT-0007 | B11: 150D涤丝 | C11: 纱线 | D11: KG | E11: 30 | F11: =SUMIFS(BOM用料!$N$5:$N$244,BOM用料!$E$5:$E$244,A11) -> 159.7736 | G11: =SUMIFS(入库明细!$O$5:$O$204,入库明细!$G$5:$G$204,A11,入库明细!$Q$5:$Q$204,"<>不合格",入库明细!$Q$5:$Q$204,"<>退货") -> 362 | H11: =SUMIFS(出库明细!$O$5:$O$204,出库明细!$G$5:$G$204,A11) -> 69.804 | I11: =G11-H11 -> 292.196 | J11: =I11-F11 -> 132.4224 | K11: =IF(I11<0,"负库存",IF(I11<E11,"低于安全库存",IF(J11<0,"订单缺料","正常"))) -> 正常 | L11: =IF(K11="正常",0,MAX(E11+F11-I11,0)) -> 0 | M11: 20 | N11: 纱线仓-A区
A12: MAT-0008 | B12: 150D涤丝 | C12: 纱线 | D12: KG | E12: 30 | F12: =SUMIFS(BOM用料!$N$5:$N$244,BOM用料!$E$5:$E$244,A12) -> 162.05608 | G12: =SUMIFS(入库明细!$O$5:$O$204,入库明细!$G$5:$G$204,A12,入库明细!$Q$5:$Q$204,"<>不合格",入库明细!$Q$5:$Q$204,"<>退货") -> 362 | H12: =SUMIFS(出库明细!$O$5:$O$204,出库明细!$G$5:$G$204,A12) -> 70.801 | I12: =G12-H12 -> 291.199 | J12: =I12-F12 -> 129.14292 | K12: =IF(I12<0,"负库存",IF(I12<E12,"低于安全库存",IF(J12<0,"订单缺料","正常"))) -> 正常 | L12: =IF(K12="正常",0,MAX(E12+F12-I12,0)) -> 0 | M12: 20 | N12: 纱线仓-A区
A13: MAT-0009 | B13: F05721 精编空花 | C13: 面料 | D13: M | E13: 80 | F13: =SUMIFS(BOM用料!$N$5:$N$244,BOM用料!$E$5:$E$244,A13) -> 275.2134 | G13: =SUMIFS(入库明细!$O$5:$O$204,入库明细!$G$5:$G$204,A13,入库明细!$Q$5:$Q$204,"<>不合格",入库明细!$Q$5:$Q$204,"<>退货") -> 3027 | H13: =SUMIFS(出库明细!$O$5:$O$204,出库明细!$G$5:$G$204,A13) -> 117.949 | I13: =G13-H13 -> 2909.051 | J13: =I13-F13 -> 2633.8376 | K13: =IF(I13<0,"负库存",IF(I13<E13,"低于安全库存",IF(J13<0,"订单缺料","正常"))) -> 正常 | L13: =IF(K13="正常",0,MAX(E13+F13-I13,0)) -> 0 | M13: 15 | N13: 面料仓-B区
A14: MAT-0010 | B14: 客供毛圈 | C14: 纱线 | D14: KG | E14: 30 | F14: =SUMIFS(BOM用料!$N$5:$N$244,BOM用料!$E$5:$E$244,A14) -> 52.53 | G14: =SUMIFS(入库明细!$O$5:$O$204,入库明细!$G$5:$G$204,A14,入库明细!$Q$5:$Q$204,"<>不合格",入库明细!$Q$5:$Q$204,"<>退货") -> 51 | H14: =SUMIFS(出库明细!$O$5:$O$204,出库明细!$G$5:$G$204,A14) -> 22.95 | I14: =G14-H14 -> 28.05 | J14: =I14-F14 -> -24.48 | K14: =IF(I14<0,"负库存",IF(I14<E14,"低于安全库存",IF(J14<0,"订单缺料","正常"))) -> 低于安全库存 | L14: =IF(K14="正常",0,MAX(E14+F14-I14,0)) -> 54.48 | M14: 20 | N14: 纱线仓-A区
A15: MAT-0011 | B15: 2*2罗文 | C15: 辅料 | D15: PCS | E15: 100 | F15: =SUMIFS(BOM用料!$N$5:$N$244,BOM用料!$E$5:$E$244,A15) -> 8.19 | G15: =SUMIFS(入库明细!$O$5:$O$204,入库明细!$G$5:$G$204,A15,入库明细!$Q$5:$Q$204,"<>不合格",入库明细!$Q$5:$Q$204,"<>退货") -> 7.8 | H15: =SUMIFS(出库明细!$O$5:$O$204,出库明细!$G$5:$G$204,A15) -> 3.51 | I15: =G15-H15 -> 4.29 | J15: =I15-F15 -> -3.9 | K15: =IF(I15<0,"负库存",IF(I15<E15,"低于安全库存",IF(J15<0,"订单缺料","正常"))) -> 低于安全库存 | L15: =IF(K15="正常",0,MAX(E15+F15-I15,0)) -> 103.9 | M15: 10 | N15: 辅料仓-C区
A16: MAT-0012 | B16: 20/1汗布 | C16: 面料 | D16: M | E16: 80 | F16: =SUMIFS(BOM用料!$N$5:$N$244,BOM用料!$E$5:$E$244,A16) -> 4.725 | G16: =SUMIFS(入库明细!$O$5:$O$204,入库明细!$G$5:$G$204,A16,入库明细!$Q$5:$Q$204,"<>不合格",入库明细!$Q$5:$Q$204,"<>退货") -> 4.5 | H16: =SUMIFS(出库明细!$O$5:$O$204,出库明细!$G$5:$G$204,A16) -> 2.025 | I16: =G16-H16 -> 2.475 | J16: =I16-F16 -> -2.25 | K16: =IF(I16<0,"负库存",IF(I16<E16,"低于安全库存",IF(J16<0,"订单缺料","正常"))) -> 低于安全库存 | L16: =IF(K16="正常",0,MAX(E16+F16-I16,0)) -> 82.25 | M16: 15 | N16: 面料仓-B区
A17: MAT-0013 | B17: F00921 | C17: 面料 | D17: M | E17: 80 | F17: =SUMIFS(BOM用料!$N$5:$N$244,BOM用料!$E$5:$E$244,A17) -> 217.14 | G17: =SUMIFS(入库明细!$O$5:$O$204,入库明细!$G$5:$G$204,A17,入库明细!$Q$5:$Q$204,"<>不合格",入库明细!$Q$5:$Q$204,"<>退货") -> 208 | H17: =SUMIFS(出库明细!$O$5:$O$204,出库明细!$G$5:$G$204,A17) -> 93.06 | I17: =G17-H17 -> 114.94 | J17: =I17-F17 -> -102.2 | K17: =IF(I17<0,"负库存",IF(I17<E17,"低于安全库存",IF(J17<0,"订单缺料","正常"))) -> 订单缺料 | L17: =IF(K17="正常",0,MAX(E17+F17-I17,0)) -> 182.2 | M17: 15 | N17: 面料仓-B区
A18: MAT-0014 | B18: 索罗娜罗纹 | C18: 面料 | D18: M | E18: 80 | F18: =SUMIFS(BOM用料!$N$5:$N$244,BOM用料!$E$5:$E$244,A18) -> 35.532 | G18: =SUMIFS(入库明细!$O$5:$O$204,入库明细!$G$5:$G$204,A18,入库明细!$Q$5:$Q$204,"<>不合格",入库明细!$Q$5:$Q$204,"<>退货") -> 38 | H18: =SUMIFS(出库明细!$O$5:$O$204,出库明细!$G$5:$G$204,A18) -> 15.228 | I18: =G18-H18 -> 22.772 | J18: =I18-F18 -> -12.76 | K18: =IF(I18<0,"负库存",IF(I18<E18,"低于安全库存",IF(J18<0,"订单缺料","正常"))) -> 低于安全库存 | L18: =IF(K18="正常",0,MAX(E18+F18-I18,0)) -> 92.76 | M18: 15 | N18: 面料仓-B区
A19: MAT-0015 | B19: 客供毛圈 | C19: 纱线 | D19: KG | E19: 30 | F19: =SUMIFS(BOM用料!$N$5:$N$244,BOM用料!$E$5:$E$244,A19) -> 59.328 | G19: =SUMIFS(入库明细!$O$5:$O$204,入库明细!$G$5:$G$204,A19,入库明细!$Q$5:$Q$204,"<>不合格",入库明细!$Q$5:$Q$204,"<>退货") -> 57.6 | H19: =SUMIFS(出库明细!$O$5:$O$204,出库明细!$G$5:$G$204,A19) -> 25.92 | I19: =G19-H19 -> 31.68 | J19: =I19-F19 -> -27.648 | K19: =IF(I19<0,"负库存",IF(I19<E19,"低于安全库存",IF(J19<0,"订单缺料","正常"))) -> 订单缺料 | L19: =IF(K19="正常",0,MAX(E19+F19-I19,0)) -> 57.648 | M19: 20 | N19: 纱线仓-A区
A20: MAT-0016 | B20: 网眼袋布 | C20: 面料 | D20: M | E20: 80 | F20: =SUMIFS(BOM用料!$N$5:$N$244,BOM用料!$E$5:$E$244,A20) -> 8.19 | G20: =SUMIFS(入库明细!$O$5:$O$204,入库明细!$G$5:$G$204,A20,入库明细!$Q$5:$Q$204,"<>不合格",入库明细!$Q$5:$Q$204,"<>退货") -> 7.8 | H20: =SUMIFS(出库明细!$O$5:$O$204,出库明细!$G$5:$G$204,A20) -> 3.51 | I20: =G20-H20 -> 4.29 | J20: =I20-F20 -> -3.9 | K20: =IF(I20<0,"负库存",IF(I20<E20,"低于安全库存",IF(J20<0,"订单缺料","正常"))) -> 低于安全库存 | L20: =IF(K20="正常",0,MAX(E20+F20-I20,0)) -> 83.9 | M20: 15 | N20: 面料仓-B区
A21: MAT-0017 | B21: 客供毛圈 | C21: 纱线 | D21: KG | E21: 30 | F21: =SUMIFS(BOM用料!$N$5:$N$244,BOM用料!$E$5:$E$244,A21) -> 4.944 | G21: =SUMIFS(入库明细!$O$5:$O$204,入库明细!$G$5:$G$204,A21,入库明细!$Q$5:$Q$204,"<>不合格",入库明细!$Q$5:$Q$204,"<>退货") -> 4.8 | H21: =SUMIFS(出库明细!$O$5:$O$204,出库明细!$G$5:$G$204,A21) -> 2.16 | I21: =G21-H21 -> 2.64 | J21: =I21-F21 -> -2.304 | K21: =IF(I21<0,"负库存",IF(I21<E21,"低于安全库存",IF(J21<0,"订单缺料","正常"))) -> 低于安全库存 | L21: =IF(K21="正常",0,MAX(E21+F21-I21,0)) -> 32.304 | M21: 20 | N21: 纱线仓-A区
A22: MAT-0018 | B22: 150D中弹丝 | C22: 纱线 | D22: KG | E22: 30 | F22: =SUMIFS(BOM用料!$N$5:$N$244,BOM用料!$E$5:$E$244,A22) -> 49.44 | G22: =SUMIFS(入库明细!$O$5:$O$204,入库明细!$G$5:$G$204,A22,入库明细!$Q$5:$Q$204,"<>不合格",入库明细!$Q$5:$Q$204,"<>退货") -> 52.16 | H22: =SUMIFS(出库明细!$O$5:$O$204,出库明细!$G$5:$G$204,A22) -> 21.6 | I22: =G22-H22 -> 30.56 | J22: =I22-F22 -> -18.88 | K22: =IF(I22<0,"负库存",IF(I22<E22,"低于安全库存",IF(J22<0,"订单缺料","正常"))) -> 订单缺料 | L22: =IF(K22="正常",0,MAX(E22+F22-I22,0)) -> 48.88 | M22: 20 | N22: 纱线仓-A区 | O22: 奕翔/伟强/恒升
A23: MAT-0019 | B23: 雪尼尔 | C23: 纱线 | D23: KG | E23: 30 | F23: =SUMIFS(BOM用料!$N$5:$N$244,BOM用料!$E$5:$E$244,A23) -> 58.71 | G23: =SUMIFS(入库明细!$O$5:$O$204,入库明细!$G$5:$G$204,A23,入库明细!$Q$5:$Q$204,"<>不合格",入库明细!$Q$5:$Q$204,"<>退货") -> 123.46 | H23: =SUMIFS(出库明细!$O$5:$O$204,出库明细!$G$5:$G$204,A23) -> 0 | I23: =G23-H23 -> 123.46 | J23: =I23-F23 -> 64.75 | K23: =IF(I23<0,"负库存",IF(I23<E23,"低于安全库存",IF(J23<0,"订单缺料","正常"))) -> 正常 | L23: =IF(K23="正常",0,MAX(E23+F23-I23,0)) -> 0 | M23: 20 | N23: 纱线仓-A区 | O23: 奕翔/伟强/恒升
A24: MAT-0020 | B24: 氨纶丝 | C24: 纱线 | D24: KG | E24: 30 | F24: =SUMIFS(BOM用料!$N$5:$N$244,BOM用料!$E$5:$E$244,A24) -> 6.18 | G24: =SUMIFS(入库明细!$O$5:$O$204,入库明细!$G$5:$G$204,A24,入库明细!$Q$5:$Q$204,"<>不合格",入库明细!$Q$5:$Q$204,"<>退货") -> 16.53 | H24: =SUMIFS(出库明细!$O$5:$O$204,出库明细!$G$5:$G$204,A24) -> 0 | I24: =G24-H24 -> 16.53 | J24: =I24-F24 -> 10.35 | K24: =IF(I24<0,"负库存",IF(I24<E24,"低于安全库存",IF(J24<0,"订单缺料","正常"))) -> 低于安全库存 | L24: =IF(K24="正常",0,MAX(E24+F24-I24,0)) -> 19.65 | M24: 20 | N24: 纱线仓-A区 | O24: 奕翔/伟强/恒升
A25: MAT-0021 | B25: 240克空气层 | C25: 辅料 | D25: PCS | E25: 100 | F25: =SUMIFS(BOM用料!$N$5:$N$244,BOM用料!$E$5:$E$244,A25) -> 748.125 | G25: =SUMIFS(入库明细!$O$5:$O$204,入库明细!$G$5:$G$204,A25,入库明细!$Q$5:$Q$204,"<>不合格",入库明细!$Q$5:$Q$204,"<>退货") -> 0 | H25: =SUMIFS(出库明细!$O$5:$O$204,出库明细!$G$5:$G$204,A25) -> 0 | I25: =G25-H25 -> 0 | J25: =I25-F25 -> -748.125 | K25: =IF(I25<0,"负库存",IF(I25<E25,"低于安全库存",IF(J25<0,"订单缺料","正常"))) -> 低于安全库存 | L25: =IF(K25="正常",0,MAX(E25+F25-I25,0)) -> 848.125 | M25: 10 | N25: 辅料仓-C区
A26: MAT-0022 | B26: 面料F02666 | C26: 面料 | D26: M | E26: 80 | F26: =SUMIFS(BOM用料!$N$5:$N$244,BOM用料!$E$5:$E$244,A26) -> 1165.5 | G26: =SUMIFS(入库明细!$O$5:$O$204,入库明细!$G$5:$G$204,A26,入库明细!$Q$5:$Q$204,"<>不合格",入库明细!$Q$5:$Q$204,"<>退货") -> 0 | H26: =SUMIFS(出库明细!$O$5:$O$204,出库明细!$G$5:$G$204,A26) -> 0 | I26: =G26-H26 -> 0 | J26: =I26-F26 -> -1165.5 | K26: =IF(I26<0,"负库存",IF(I26<E26,"低于安全库存",IF(J26<0,"订单缺料","正常"))) -> 低于安全库存 | L26: =IF(K26="正常",0,MAX(E26+F26-I26,0)) -> 1245.5 | M26: 15 | N26: 面料仓-B区
